Workbook

Sheet Ограничения оценки ВНУТРЕННИЕ!
A1: № | B1: Ограничение | C1: Пояснение
A2: 1
A3: 2
A4: 3
A5: 4
A6: 5
A7: 6
A8: 7
A9: 8
A10: 9
A11: 10

Sheet Лист изменений
A1: 45260
A2: Изменения ФС
A3: 1. | B3: Выделил отдельный раздел по отражению базовых данных по БДР и БДДС из раздела 4.5. Экономика проектов (Уточнил перечень документов и хоз. Операций)
A4: 2. | B4: Перенес трансляцию данных распределенной зарплаты из раздела 4.5. в разделы 7.3. и 7.4. по распредеелнию ЗП, и ОПР/ОХР, соответсвенно
A5: 3. | B5: Добавил строку "Формирование плана доходов по проектам" в раздел 7.1. Бизнес-план
A6: 4. | B6: Раздел 1.6. "переквалифицировал" в Базовый
A7: 5. | B7: Уточнил содержание раздела 5.1.План работ подразделений В новой версии предлагаю его читать как работа РСП (Декомпозиция структуры проекта в рамках работ подарделений, переквалифицировал в Базовый функционал
B8: Уточнил раздел 5.4. "… по ролям", перенес в него работы с прогнозом трудозатрат по ролям
B9: Уточнил терминологию п 2.6. "Технологические графики"
B10: Перенес работу с оперативной загрузкой из раздела 5.1. (Базовый) в раздел 5.3 (весь раздел сформулировал как "Оперативное управление работами и загрузкой исполнителй)
B11: Добавил новый раздел 3.5. "Мониторинг процесса обеспечения ТМЦ под проект в Контуре PM" Как наша гипотеха по тому какая функциональность необходима дл Инжиниринга
B12: Выделил отдельные разделы по распределению ОПР/ОХР в проектном контуре
B13: Перенес получение факта из БП 3 в раздел Интеграции
B14: Отчет по EVA перенесли в базовый функционал в раздел 4.3.
B15: Отчет Динамика экономики перенесли в базовый функционал в раздел 4.4.
B16: Выделена отдельной строкой обмен первичными документами с БП, изменена оценка
B17: Обмен с ЗУП разделен на 2 строки: 1. Получение Начсиленнйо ЗП для целей распределения ЗП в ERP, 2. Часто встречающийся запрос на синхронизацию структуры ТР с кадровыми данными (Прием, перевод, увольнение, ставки ТР)
A18: Изменения в оценке
B19: Изменил параметры ставки с 24 года: - Ставка Стандартизированных преоктов (кейс и проф/мини) 4500 , - Ставка ПРОФ проектов 4900; - Ставка КОРП проектов 5500 Вторая и далее очереди оцениваются "по умолчанию" с учетом длительности предыдущих очередей
B20: Добавил параметры и расчет типа проекта п критериям и подстановку ставки в соответсвии с типом проектв на листы оценок по каждой очереди
B21: Изменил коэффициенты разработки для 500 и 1000+ по умолчанию (в меньшую сторону до х3)
B22: Добавил индикаторы "адекватности" сроков по оценкам по очередям
B23: скорректировал расчет этапов обучения
B24: Скорректировал расчет сроков по этапам
A25: 45321
B26: Уточнил перечень хоз операция, в п. 4.4.
B27: Переформулировали п. 7.8, 7.1. ( с сохранением сути)
B28: Сделал автозаполнение критериев отнесения к ПРОФ и КОРП из Содержания проекта
A29: 45335
B30: Добавили строки прочего функицонала (Использование модулей для ERP и ERP+УХ
A31: 45717 | B31: Добавили Фонд компании и резервы на риски договора
A32: 45805 | B32: Внесена колонка с функционалом и ограничениями реализации на РМ5

Sheet 1.Содержание проекта
A1: Содержание проекта | F1: Заполнено?
A2: 1.Обоснование проекта (потребности, предпосылки) | F2: Группа
A3: Автоматизируемые виды деятельности | D3: Субпродукт (выпускаемый продукт/услуга) | F3: Группа
A4: Выбор из списка (выбрать): | F4: =ISBLANK(B4) -> TRUE
F5: =ISBLANK(B5) -> TRUE
F6: =ISBLANK(B6) -> TRUE
F7: =ISBLANK(B7) -> TRUE
F8: =ISBLANK(B8) -> TRUE
F9: =ISBLANK(B9) -> TRUE
F10: =ISBLANK(B10) -> TRUE
A11: Свои варианты (вписать): | F11: =ISBLANK(B11) -> TRUE
F12: =ISBLANK(B12) -> TRUE
F13: =ISBLANK(B13) -> TRUE
F14: =ISBLANK(B14) -> TRUE
F15: =ISBLANK(B15) -> TRUE
F16: =ISBLANK(B16) -> TRUE
F17: =ISBLANK(B17) -> TRUE
A18: Бизнес потребность (для чего реализуется проект, желательно, с конкретными измеримыми показателями) | E18: Текстовые комментарии | F18: Группа
A19: Выбор из списка (выбрать): | F19: =ISBLANK(B19) -> TRUE
F20: =ISBLANK(B20) -> TRUE
F21: =ISBLANK(B21) -> TRUE
F22: =ISBLANK(B22) -> TRUE
F23: =ISBLANK(B23) -> TRUE
F24: =ISBLANK(B24) -> TRUE
F25: =ISBLANK(B25) -> TRUE
A26: Свои варианты (вписать): | F26: =ISBLANK(B26) -> TRUE
F27: =ISBLANK(B27) -> TRUE
F28: =ISBLANK(B28) -> TRUE
F29: =ISBLANK(B29) -> TRUE
F30: =ISBLANK(B30) -> TRUE
F31: =ISBLANK(B31) -> TRUE
F32: =ISBLANK(B32) -> TRUE
A33: Предпосылки (что сейчас не так - указываются факторы, которые мешают достигнуть бизнес-потребностей, а также история и проблематика, приведшие к идее старта проекта) | E33: Текстовые комментарии | F33: Группа
A34: Выбор из списка (выбрать): | F34: =ISBLANK(B34) -> TRUE
F35: =ISBLANK(B35) -> TRUE
F36: =ISBLANK(B36) -> TRUE
F37: =ISBLANK(B37) -> TRUE
F38: =ISBLANK(B38) -> TRUE
F39: =ISBLANK(B39) -> TRUE
F40: =ISBLANK(B40) -> TRUE
...

Sheet параметры расчета
C1: Ставка с 25 года | D1: Ставка с 24 года | E1: Ставки 23 года | F1: Изменение ставки
B2: Расчет Ставки | C2: =IF('1.Содержание проекта'!#REF!="КОРП-проект",'параметры расчета'!C5,IF('1.Содержание проекта'!#REF!>12,'параметры расчета'!C4,'параметры расчета'!C3)) -> #REF! | D2: #REF! | H2: Критерии отнесения к типу преокта по ставке
B3: Ставка Кейс; ПРОФ/мини | C3: 5000 | D3: 4500 | E3: 4200 | F3: =C3/E3-1 -> 0.19047619
B4: Ставка ПРОФ | C4: 5500 | D4: 4900 | E4: 4500 | F4: =C4/E4-1 -> 0.22222222 | H4: 1. Необходимо описывать Бизнес-процессы 2. Более 200 пользователей 3. Не стандартные формы документов (Без изменения состава работ и документации) 4. Требуется нагрузочное тестирование
B5: Ставка Заказные | C5: 6500 | D5: 5500 | E5: 4900 | F5: =C5/E5-1 -> 0.32653061 | H5: 1. Технология заказчика (в т.ч. Документация, которая подразумевает расширение состава работ) 2. Оптимизация бизнес-процессов 3. Методология 4. численность Заказчика более 1000 сотрудников (КОРП заказчик) 5. Более 500 пользователей 6. Заявлена документация по ИБ
B6: Резерв РПО | C6: 0.2 | D6: 0.2
B8: Функциональный объем | C8: Базовый/Проф/Экспертный функционал
B9: Темплан и контрактация | C9: ГРУППА | D9: Да
B10: Производственная программа | C10: Базовый | D10: Да | E10: 2
B11: Формирование производственной программы | D11: Да
B12: План-фактный анализ по программе | D12: Да
B13: Тематический план | D13: Да
B14: Сводная загрузка | C14: Базовый | D14: Да | E14: 1
B15: Анализ загрузки подразделений и специальностей по задачам производственной программы | D15: Нет
B16: Ручное выравнивание загрузки подразделений по задачам портфеля проектов | D16: Нет
B17: Расчет цены контракта | C17: ПРОФ | D17: Нет | E17: 2
B18: Расчет цены контракта | D18: Нет
B19: Планирование и мониторинг прохождения тендера | D19: Нет
B20: Выдача поручений по разработке догововора | D20: Нет
B21: Моделирвоание инвест. Портфеля. Ранжирование заявок на проекты. | C21: ПРОФ | D21: Нет | E21: 3
B22: Формирование заявок на проект. Мониторинг состояния завок. | C22: ПРОФ | D22: Нет
B23: Оценка соответствия заявленных проектов стратегическим целям компании | C23: ПРОФ | D23: Нет
B24: Регистрация значений показателей ээфективности проектов (Внутренняя ставка доходности, срок окупаемости,индекс прибыльности, чистый денежный поток, чистая приведенная стоимость) | C24: ПРОФ | D24: Нет
B25: Расчет итогового балла проектов по показателеям эффективности. | C25: ПРОФ | D25: Нет
B26: Формирование бизнес плана по портфелю проектов. | C26: ПРОФ | D26: Нет
B27: Мониторинг договорной компании | C27: ПРОФ | D27: Да | E27: 2
B28: Регистрация юридических условий договора и дополнительных соглашений | C28: ПРОФ | D28: Нет
B29: Согласование и монитринг статусов договора | C29: ПРОФ | D29: Нет
B30: Актуализация БДДС по данным договора | C30: ПРОФ | D30: Нет
B31: Хранение файлов и отсканированных копий договора | C31: ПРОФ | D31: Нет
B32: Мониторинг фаз проектов портфеля (Gate) | C32: ПРОФ | D32: Да | E32: 1
B33: Мониторинг показателей портфеля проектов по методике ворот качества в панели руководителя | C33: ПРОФ | D33: Нет
B34: Управление ЖЦ проектов (портфеля проектов) по методике ворот качества | C34: ПРОФ | D34: Нет
B35: KPI портфеля проектов | C35: ПРОФ | D35: Да | E35: 2
B36: Мониторинг KPI портфеля проектов | D36: Нет
B37: Анализ плановых показателей трудоемкости, бюджетов и объемов работ запланирванных по портфелю и соттоветствующих плановых и фактических показателей проектов входящих в портфель | D37: Нет
B38: Оптимизация темтического плана | C38: Экспертный | D38: Нет | E38: 10
B39: Управление работами и сроками | C39: ГРУППА | D39: Нет
B40: Сформировать календарные планы проектов | C40: Базовый | D40: Да | E40: 2
B41: Регистрация паспорта проекта | C41: Базовый | D41: Да
...

Sheet 2.ФС для Заполнения
AA1: Ставка
B2: 2. Заполнение функционального объема (строго на закладке "ФС для Заполнения") | AA2: 1. Орг объем: Количество пользователей и сотрудников организации всего Заполняются ТОЛЬКО ячейки выделенные желтым цветом. Используется для расчета фаз 5.2,6,7 | AC2: ДО 200 | AF2: =AC2 -> ДО 200 | AI2: =AC2 -> ДО 200 | AL2: =AC2 -> ДО 200
B3: 2.1. Колонка "ДА"/"НЕТ" по принципу Функциональной спецификации На уровне записей устанавливается вручную. Группа определяется по формуле | AA3: Орг. Объем | AC3: Итого | AD3: в т.ч. В городе присутствия | AE3: в т.ч. В регионах (с командировкой) | AF3: Итого | AG3: в т.ч. В городе присутствия | AH3: в т.ч. В регионах (с командировкой) | AI3: Итого | AJ3: в т.ч. В городе присутствия | AK3: в т.ч. В регионах (с командировкой) | AL3: Итого | AM3: в т.ч. В городе присутствия | AN3: в т.ч. В регионах (с командировкой)
B4: 2.2. Необходимость методической проработки в рамках проекта: Первоначально определяется по формуле (Требуется или предоставляется Заказчиком). Если в рамках проекта требуется методическая проработка, то значение меняется вручную на "Необходимо разработать" | AA4: в т.ч. Пользователей | AC4: =AD4+AE4 -> 30 | AD4: =SUM(AD5:AD6) -> 30 | AE4: =SUM(AE5:AE6) -> 0 | AF4: =AG4+AH4 -> 95 | AG4: =SUM(AG5:AG6) -> 95 | AH4: =SUM(AH5:AH6) -> 0 | AI4: =AJ4+AK4 -> 95 | AJ4: =SUM(AJ5:AJ6) -> 95 | AK4: =SUM(AK5:AK6) -> 0 | AL4: =AM4+AN4 -> 0 | AM4: =SUM(AM5:AM6) -> 0 | AN4: =SUM(AN5:AN6) -> 0
B5: 2.3.Объем нагрузочного тестирования: Определяется количество сценариев автоматически Рассчитывается по формуле если функционал отмечен как "Да" | AA5: Количество РП, РПО, Рук. Отделов | AC5: =AD5+AE5 -> 10 | AD5: 10 | AF5: =AG5+AH5 -> 20 | AG5: 20 | AI5: =AJ5+AK5 -> 20 | AJ5: 20 | AL5: =AM5+AN5 -> 0
AA6: Количество Исполнителей Работ | AC6: =AD6+AE6 -> 20 | AD6: 20 | AF6: =AG6+AH6 -> 75 | AG6: 75 | AI6: =AJ6+AK6 -> 75 | AJ6: 75 | AL6: =AM6+AN6 -> 0
AA7: в т.ч. Численность Рабочей Группы Заказчика (Ключевые пользователи к обучению) | AC7: =AD7+AE7 -> 5 | AD7: 5 | AF7: =AG7+AH7 -> 5 | AG7: 5 | AI7: =AJ7+AK7 -> 5 | AJ7: 5 | AL7: =AM7+AN7 -> 0
AC8: БЗ Проеткная дирекция | AF8: Комплексный Заказной проект проект | AI8: БЗ Экономический блок | BW8: Полная рентабельность | BX8: Полная рентабельность | CC8: Полная рентабельность + бюджетирование + казна | CF8: Проектная продукция | CJ8: Упр. Подражделениями | CL8: Тем. План
A9: № п.п | B9: Функциональный объем | C9: Функциональный объем РМ5 и особенности реализации | D9: Аргументы для Заказчика | E9: Функциональный заказчик по блоку (ФИО, должность) | F9: Тип функционала | G9: Тип проекта | H9: PM ПРОФ | I9: УНФ+PM | J9: PM КОРП | K9: ERP+PM | L9: PM5 | M9: Вес функционала Story Points | N9: Story Points Итого | O9: 1 очередь | P9: НМД | Q9: Нагрузочное | R9: 2 очередь | S9: НМД | T9: Нагрузочное | U9: 3 очередь | V9: НМД | W9: Нагрузочное | X9: Развитие | Y9: НМД | Z9: Нагрузочное | AA9: Да/Нет | AB9: Доп. вопросы | AC9: 1 очередь | AD9: НМД | AE9: Комментарий | AF9: 2 очередь | AG9: НМД | AH9: Комментарий | AI9: 3 очередь | AJ9: НМД | AK9: Комментарий | AL9: Развитие | AM9: НМД | AN9: Комментарий | AP9: Шаблоны. Не править | AQ9: Story Points | AR9: По функциональности | AS9: Кейс-проект | AT9: Кейс по готовности PM5 | AU9: БЗ Проеткная дирекция | AV9: БЗ Экономический блок | AW9: Базовый функционал + экономика оптимально (РСП, то, что готово) | AX9: Комплексный ПРОФ проект | AY9: Комплексный Заказной проект проект | AZ9: Заказной+ консалтинг | BA9: По позиционированию | BB9: Акционеры хотят фин.эк. прозрачности (отчеты в сроки через ФД или ПЭО) | BC9: Системный директор /системные ТОПы – комплексная бизнес-система | BD9: Гос.контракты (военные контракты) конструкторов/труд.производства | BE9: Планирование сроков, загрузки и диспетчеризация работ подразделений | BF9: Формирование моделей и физических объектов по моделям в сроки Было: Директор по производству: Результаты (Продукт проекта) в сроки | BG9: Управление сроками, ресурсами и лимитами корпоративных проектов от уровня холдинга до КБ и завода | BH9: Управление корпоративными проектами развития и инвест.проектами | BI9: Руководитель структурного подразделения: сроки, ресурсы, финансы | BJ9: Структурирование проектной деятельности | BK9: Моделирование численности (вкл. Формирование тем. плана) | BL9: Систематизация продаж проектов (вкл. формирование стоимости контракта) | BM9: Операционное управление проектом (пока не наш рынок) | BN9: Технический переход с УПО 1.3 | BO9: ИТ-проект как Большая мечта | BP9: Импортозамещение | BQ9: По функциональности | BS9: Кейс-проект | BT9: Кейс по готовности PM5 | BU9: БЗ Проеткная дирекция | BV9: БЗ Экономический блок | BW9: Инжиниринг | BX9: Базовый функционал + экономика оптимально (РСП, то, что готово) | BY9: Комплексный ПРОФ проект | BZ9: Комплексный Заказной проект проект | CA9: Заказной+ консалтинг | CB9: По позиционированию | CC9: Акционеры хотят фин.эк. прозрачности (отчеты в сроки через ФД или ПЭО) | CD9: Системный директор /системные ТОПы – комплексная бизнес-система | CE9: Гос.контракты (военные контракты) конструкторов/труд.производства | CF9: Планирование сроков, загрузки и диспетчеризация работ подразделений | CG9: Формирование моделей и физических объектов по моделям в сроки Было: Директор по производству: Результаты (Продукт проекта) в сроки | CH9: Управление сроками, ресурсами и лимитами корпоративных проектов от уровня холдинга до КБ и завода | CI9: Управление корпоративными проектами развития и инвест.проектами | CJ9: Руководитель структурного подразделения: сроки, ресурсы, финансы | CK9: Структурирование проектной деятельности | CL9: Моделирование численности (вкл. Формирование тем. плана) | CM9: Систематизация продаж проектов (вкл. формирование стоимости контракта) | CN9: Операционное управление проектом (пока не наш рынок) | CO9: Технический переход с УПО 1.3 | CP9: ИТ-проект как Большая мечта | CQ9: Импортозамещение | CR9: Требуется НМД эталлон
A10: 1. | B10: Тем план и контрактация | F10: ГРУППА | G10: ГРУППА | H10: ГРУППА | I10: ГРУППА | J10: ГРУППА | K10: ГРУППА | L10: ГРУППА | M10: =SUM(M37,M33,M31,M27,M20,M17,M14,M11) -> 28 | N10: =SUM(N37,N33,N31,N27,N20,N17,N14,N11) -> 27 | O10: =SUM(O37,O33,O31,O27,O20,O17,O14,O11) -> 5 | P10: =SUM(P37,P33,P31,P27,P20,P17,P14,P11) -> 0 | Q10: =SUM(Q37,Q33,Q31,Q27,Q20,Q17,Q14,Q11) -> 3 | R10: =SUM(R37,R33,R31,R27,R20,R17,R14,R11) -> 18 | S10: =SUM(S37,S33,S31,S27,S20,S17,S14,S11) -> 0 | T10: =SUM(T37,T33,T31,T27,T20,T17,T14,T11) -> 8 | ... Z10: =SUM(Z37,Z33,Z31,Z27,Z20,Z17,Z14,Z11) -> 0 | AA10: =IF(N10>0,"ДА","НЕТ") -> ДА | AC10: =IF(O10>0,"ДА","НЕТ") -> ДА | AF10: =IF(R10>0,"ДА","НЕТ") -> ДА | AI10: =IF(U10>0,"ДА","НЕТ") -> ДА | AL10: =IF(X10>0,"ДА","НЕТ") -> НЕТ | AS10: =SUM(AS37,AS33,AS31,AS27,AS20,AS17,AS14,AS11) -> 6 | AT10: =SUM(AT37,AT33,AT31,AT27,AT20,AT17,AT14,AT11) -> 5 | AU10: =SUM(AU37,AU33,AU31,AU27,AU20,AU17,AU14,AU11) -> 5 | AV10: =SUM(AV37,AV33,AV31,AV27,AV20,AV17,AV14,AV11) -> 4 | AW10: =SUM(AW37,AW33,AW31,AW27,AW20,AW17,AW14,AW11) -> 8 | AX10: =SUM(AX37,AX33,AX31,AX27,AX20,AX17,AX14,AX11) -> 10 | AY10: =SUM(AY37,AY33,AY31,AY27,AY20,AY17,AY14,AY11) -> 18 | AZ10: =SUM(AZ37,AZ33,AZ31,AZ27,AZ20,AZ17,AZ14,AZ11) -> 28 | BB10: =SUM(BB37,BB33,BB31,BB27,BB20,BB17,BB14,BB11) -> 6 | BC10: =SUM(BC37,BC33,BC31,BC27,BC20,BC17,BC14,BC11) -> 8 | BD10: =SUM(BD37,BD33,BD31,BD27,BD20,BD17,BD14,BD11) -> 3 | BE10: =SUM(BE37,BE33,BE31,BE27,BE20,BE17,BE14,BE11) -> 3 | BF10: =SUM(BF37,BF33,BF31,BF27,BF20,BF17,BF14,BF11) -> 0 | BG10: =SUM(BG37,BG33,BG31,BG27,BG20,BG17,BG14,BG11) -> 16 | BH10: =SUM(BH37,BH33,BH31,BH27,BH20,BH17,BH14,BH11) -> 16 | BI10: =SUM(BI37,BI33,BI31,BI27,BI20,BI17,BI14,BI11) -> 0 | ... BP10: =SUM(BP37,BP33,BP31,BP27,BP20,BP17,BP14,BP11) -> 0 | BS10: =IF(AS10>0,"ДА","НЕТ") -> ДА | BT10: =IF(AT10>0,"ДА","НЕТ") -> ДА | BU10: =IF(AU10>0,"ДА","НЕТ") -> ДА | BV10: =IF(AV10>0,"ДА","НЕТ") -> ДА | BW10: =IF(AS10>0,"ДА","НЕТ") -> ДА | BX10: =IF(AW10>0,"ДА","НЕТ") -> ДА | BY10: =IF(AX10>0,"ДА","НЕТ") -> ДА | BZ10: =IF(AY10>0,"ДА","НЕТ") -> ДА | CA10: =IF(AZ10>0,"ДА","НЕТ") -> ДА | CC10: =IF(BB10>0,"ДА","НЕТ") -> ДА | CD10: =IF(BC10>0,"ДА","НЕТ") -> ДА | CE10: =IF(BD10>0,"ДА","НЕТ") -> ДА | CF10: =IF(BE10>0,"ДА","НЕТ") -> ДА | CG10: =IF(BF10>0,"ДА","НЕТ") -> НЕТ | CH10: =IF(BG10>0,"ДА","НЕТ") -> ДА | CI10: =IF(BH10>0,"ДА","НЕТ") -> ДА | CJ10: =IF(BI10>0,"ДА","НЕТ") -> НЕТ | ... CQ10: =IF(BP10>0,"ДА","НЕТ") -> НЕТ
A11: 1.1. | B11: Производственная программа | F11: Базовый | G11: Кейс-проект | H11: Да | I11: Да | J11: Да | K11: Да | L11: В разработке | M11: 2 | N11: =SUM(O11,R11,U11,X11) -> 6 | O11: =IF(AC11="ДА",$M11,"") -> 2 | Q11: =IF(AC11="ДА",ROUNDUP(O11/5,0),0) -> 1 | R11: =IF(AF11="ДА",$M11,"") -> 2 | T11: =IF(AF11="ДА",ROUNDUP(R11/5,0),0) -> 1 | U11: =IF(AI11="ДА",$M11,"") -> 2 | W11: =IF(AI11="ДА",ROUNDUP(U11/5,0),0) -> 1 | X11: =IF(AL11="ДА",$M11,"") | Z11: =IF(AL11="ДА",ROUNDUP(X11/5,0),0) -> 0 | AA11: =IF(OR(AC11="ДА",AF11="ДА",AI11="ДА",AL11="ДА"),"ДА","НЕТ") -> ДА | AC11: =IF(AC$8=$BT$9,$BT11,IF(AC$8=$BS$9,$BS11,IF(AC$8=$BU$9,$BU11,IF(AC$8=$BV$9,$BV11,IF(AC$8=$BW$9,$BW11,IF(AC$8=$BX$9,$BX11,IF(AC$8=$BY$9,$BY11,IF(AC$8=$BZ$9,$BZ11,IF(AC$8=$CA$9,$CA11,IF(AC$8=$CC$9,$CC11,IF(AC$8=$CD$9,$CD11,IF(AC$8=$CE$9,$CE11,IF(AC$8=$CF$9,$CF11,IF(AC$8=$CG$9,$CG11,IF(AC$8=$CH$9,$CH11,IF(AC$8=$CI$9,$CI11,IF(AC$8=$CJ$9,$CJ11,IF(AC$8=$CK$9,$CK11,IF(AC$8=$CL$9,$CL11,IF(AC$8=$CM$9,$CM11,IF(AC$8=$CN$9,$CN11,IF(AC$8=$CO$9,$CO11,IF(AC$8=$CP$9,$CP11,IF(AC$8=$CQ$9,$CQ11,"НЕТ")))))))))))))))))))))))) -> ДА | AD11: =IF(AC11="НЕТ","Не требуется",$CR11) -> Не требуется | AF11: =IF(AF$8=$BT$9,$BT11,IF(AF$8=$BS$9,$BS11,IF(AF$8=$BU$9,$BU11,IF(AF$8=$BV$9,$BV11,IF(AF$8=$BW$9,$BW11,IF(AF$8=$BX$9,$BX11,IF(AF$8=$BY$9,$BY11,IF(AF$8=$BZ$9,$BZ11,IF(AF$8=$CA$9,$CA11,IF(AF$8=$CC$9,$CC11,IF(AF$8=$CD$9,$CD11,IF(AF$8=$CE$9,$CE11,IF(AF$8=$CF$9,$CF11,IF(AF$8=$CG$9,$CG11,IF(AF$8=$CH$9,$CH11,IF(AF$8=$CI$9,$CI11,IF(AF$8=$CJ$9,$CJ11,IF(AF$8=$CK$9,$CK11,IF(AF$8=$CL$9,$CL11,IF(AF$8=$CM$9,$CM11,IF(AF$8=$CN$9,$CN11,IF(AF$8=$CO$9,$CO11,IF(AF$8=$CP$9,$CP11,IF(AF$8=$CQ$9,$CQ11,"НЕТ")))))))))))))))))))))))) -> ДА | AG11: =IF(AG$8=$BT$9,$BT11,IF(AG$8=$BS$9,$BS11,IF(AG$8=$BU$9,$BU11,IF(AG$8=$BV$9,$BV11,IF(AG$8=$BW$9,$BW11,IF(AG$8=$BX$9,$BX11,IF(AG$8=$BY$9,$BY11,IF(AG$8=$BZ$9,$BZ11,IF(AG$8=$CA$9,$CA11,IF(AG$8=$CC$9,$CC11,IF(AG$8=$CD$9,$CD11,IF(AG$8=$CE$9,$CE11,IF(AG$8=$CF$9,$CF11,IF(AG$8=$CG$9,$CG11,IF(AG$8=$CH$9,$CH11,IF(AG$8=$CI$9,$CI11,IF(AG$8=$CJ$9,$CJ11,IF(AG$8=$CK$9,$CK11,IF(AG$8=$CL$9,$CL11,IF(AG$8=$CM$9,$CM11,IF(AG$8=$CN$9,$CN11,IF(AG$8=$CO$9,$CO11,IF(AG$8=$CP$9,$CP11,IF(AG$8=$CQ$9,$CQ11,"НЕТ")))))))))))))))))))))))) -> НЕТ | AH11: =IF(AH$8=$BT$9,$BT11,IF(AH$8=$BS$9,$BS11,IF(AH$8=$BU$9,$BU11,IF(AH$8=$BV$9,$BV11,IF(AH$8=$BW$9,$BW11,IF(AH$8=$BX$9,$BX11,IF(AH$8=$BY$9,$BY11,IF(AH$8=$BZ$9,$BZ11,IF(AH$8=$CA$9,$CA11,IF(AH$8=$CC$9,$CC11,IF(AH$8=$CD$9,$CD11,IF(AH$8=$CE$9,$CE11,IF(AH$8=$CF$9,$CF11,IF(AH$8=$CG$9,$CG11,IF(AH$8=$CH$9,$CH11,IF(AH$8=$CI$9,$CI11,IF(AH$8=$CJ$9,$CJ11,IF(AH$8=$CK$9,$CK11,IF(AH$8=$CL$9,$CL11,IF(AH$8=$CM$9,$CM11,IF(AH$8=$CN$9,$CN11,IF(AH$8=$CO$9,$CO11,IF(AH$8=$CP$9,$CP11,IF(AH$8=$CQ$9,$CQ11,"НЕТ")))))))))))))))))))))))) -> НЕТ | AI11: =IF(AI$8=$BT$9,$BT11,IF(AI$8=$BS$9,$BS11,IF(AI$8=$BU$9,$BU11,IF(AI$8=$BV$9,$BV11,IF(AI$8=$BW$9,$BW11,IF(AI$8=$BX$9,$BX11,IF(AI$8=$BY$9,$BY11,IF(AI$8=$BZ$9,$BZ11,IF(AI$8=$CA$9,$CA11,IF(AI$8=$CC$9,$CC11,IF(AI$8=$CD$9,$CD11,IF(AI$8=$CE$9,$CE11,IF(AI$8=$CF$9,$CF11,IF(AI$8=$CG$9,$CG11,IF(AI$8=$CH$9,$CH11,IF(AI$8=$CI$9,$CI11,IF(AI$8=$CJ$9,$CJ11,IF(AI$8=$CK$9,$CK11,IF(AI$8=$CL$9,$CL11,IF(AI$8=$CM$9,$CM11,IF(AI$8=$CN$9,$CN11,IF(AI$8=$CO$9,$CO11,IF(AI$8=$CP$9,$CP11,IF(AI$8=$CQ$9,$CQ11,"НЕТ")))))))))))))))))))))))) -> ДА | AJ11: =IF(AJ$8=$BT$9,$BT11,IF(AJ$8=$BS$9,$BS11,IF(AJ$8=$BU$9,$BU11,IF(AJ$8=$BV$9,$BV11,IF(AJ$8=$BW$9,$BW11,IF(AJ$8=$BX$9,$BX11,IF(AJ$8=$BY$9,$BY11,IF(AJ$8=$BZ$9,$BZ11,IF(AJ$8=$CA$9,$CA11,IF(AJ$8=$CC$9,$CC11,IF(AJ$8=$CD$9,$CD11,IF(AJ$8=$CE$9,$CE11,IF(AJ$8=$CF$9,$CF11,IF(AJ$8=$CG$9,$CG11,IF(AJ$8=$CH$9,$CH11,IF(AJ$8=$CI$9,$CI11,IF(AJ$8=$CJ$9,$CJ11,IF(AJ$8=$CK$9,$CK11,IF(AJ$8=$CL$9,$CL11,IF(AJ$8=$CM$9,$CM11,IF(AJ$8=$CN$9,$CN11,IF(AJ$8=$CO$9,$CO11,IF(AJ$8=$CP$9,$CP11,IF(AJ$8=$CQ$9,$CQ11,"НЕТ")))))))))))))))))))))))) -> НЕТ | AK11: =IF(AK$8=$BT$9,$BT11,IF(AK$8=$BS$9,$BS11,IF(AK$8=$BU$9,$BU11,IF(AK$8=$BV$9,$BV11,IF(AK$8=$BW$9,$BW11,IF(AK$8=$BX$9,$BX11,IF(AK$8=$BY$9,$BY11,IF(AK$8=$BZ$9,$BZ11,IF(AK$8=$CA$9,$CA11,IF(AK$8=$CC$9,$CC11,IF(AK$8=$CD$9,$CD11,IF(AK$8=$CE$9,$CE11,IF(AK$8=$CF$9,$CF11,IF(AK$8=$CG$9,$CG11,IF(AK$8=$CH$9,$CH11,IF(AK$8=$CI$9,$CI11,IF(AK$8=$CJ$9,$CJ11,IF(AK$8=$CK$9,$CK11,IF(AK$8=$CL$9,$CL11,IF(AK$8=$CM$9,$CM11,IF(AK$8=$CN$9,$CN11,IF(AK$8=$CO$9,$CO11,IF(AK$8=$CP$9,$CP11,IF(AK$8=$CQ$9,$CQ11,"НЕТ")))))))))))))))))))))))) -> НЕТ | AL11: =IF(AL$8=$BT$9,$BT11,IF(AL$8=$BS$9,$BS11,IF(AL$8=$BU$9,$BU11,IF(AL$8=$BV$9,$BV11,IF(AL$8=$BW$9,$BW11,IF(AL$8=$BX$9,$BX11,IF(AL$8=$BY$9,$BY11,IF(AL$8=$BZ$9,$BZ11,IF(AL$8=$CA$9,$CA11,IF(AL$8=$CC$9,$CC11,IF(AL$8=$CD$9,$CD11,IF(AL$8=$CE$9,$CE11,IF(AL$8=$CF$9,$CF11,IF(AL$8=$CG$9,$CG11,IF(AL$8=$CH$9,$CH11,IF(AL$8=$CI$9,$CI11,IF(AL$8=$CJ$9,$CJ11,IF(AL$8=$CK$9,$CK11,IF(AL$8=$CL$9,$CL11,IF(AL$8=$CM$9,$CM11,IF(AL$8=$CN$9,$CN11,IF(AL$8=$CO$9,$CO11,IF(AL$8=$CP$9,$CP11,IF(AL$8=$CQ$9,$CQ11,"НЕТ")))))))))))))))))))))))) -> НЕТ | AM11: =IF(AL11="НЕТ","Не требуется",$CR11) -> Не требуется | AS11: =IF(BS11="ДА",$M11,"") -> 2 | AT11: =IF(BT11="ДА",$M11,"") -> 2 | AU11: =IF(BU11="ДА",$M11,"") -> 2 | AV11: =IF(BV11="ДА",$M11,"") -> 2 | AW11: =IF(BW11="ДА",$M11,"") -> 2 | AX11: =IF(BY11="ДА",$M11,"") -> 2 | AY11: =IF(BZ11="ДА",$M11,"") -> 2 | AZ11: =IF(CA11="ДА",$M11,"") -> 2 | BB11: =IF(CC11="ДА",$M11,"") -> 2 | BC11: =IF(CD11="ДА",$M11,"") -> 2 | BD11: =IF(CE11="ДА",$M11,"") -> 2 | BE11: =IF(CF11="ДА",$M11,"") -> 2 | BF11: =IF(CG11="ДА",$M11,"") | BG11: =IF(CH11="ДА",$M11,"") -> 2 | BH11: =IF(CI11="ДА",$M11,"") -> 2 | BI11: =IF(CJ11="ДА",$M11,"") | ... BP11: =IF(CQ11="ДА",$M11,"") | BS11: ДА | BT11: ДА | BU11: ДА | BV11: ДА | BW11: ДА | BX11: ДА | BY11: ДА | BZ11: ДА | CA11: ДА | CC11: ДА | CD11: ДА | CE11: ДА | CF11: ДА | CG11: НЕТ | CH11: ДА | CI11: ДА | CJ11: НЕТ | CK11: ДА | CL11: ДА | CM11: ДА | CN11: НЕТ | CO11: НЕТ | CP11: НЕТ | CQ11: НЕТ | CR11: Не требуется | CS11: НЕТ | CT11: НЕТ
B12: Формирование производственной программы | C12: Частично! Свод по производственной программе- в панели руководителя и отчетах, отдельной сущности нет. Есть доходные объемы, а доходов собственно нет. Есть БДР и БДДС в структуре, а так же в табличном редакторе, так же есть доходные объемы и расходные (ресурсы)
B13: План-фактный анализ по программе | C13: Пока не весь функционал ПФА по программе есть как в РМ4. Нет необходимости в полном повторении РМ4, потому что по сценарию РМ5 он такой не нужен. ПФА существует в виде отчетов, а так же с помощью таблиных редакторов, где присутствует план, а так же факт+прогноз.
A14: 1.2. | B14: Сводная загрузка | F14: Базовый | G14: Кейс-проект | H14: Да | I14: Да | J14: Да | K14: Да | L14: Да | M14: 1 | N14: =SUM(O14,R14,U14,X14) -> 2 | O14: =IF(AC14="ДА",$M14,"") -> 1 | Q14: =IF(AC14="ДА",ROUNDUP(O14/5,0),0) -> 1 | R14: =IF(AF14="ДА",$M14,"") -> 1 | T14: =IF(AF14="ДА",ROUNDUP(R14/5,0),0) -> 1 | U14: =IF(AI14="ДА",$M14,"") | W14: =IF(AI14="ДА",ROUNDUP(U14/5,0),0) -> 0 | X14: =IF(AL14="ДА",$M14,"") | Z14: =IF(AL14="ДА",ROUNDUP(X14/5,0),0) -> 0 | AA14: =IF(OR(AC14="ДА",AF14="ДА",AI14="ДА",AL14="ДА"),"ДА","НЕТ") -> ДА | AC14: =IF(AC$8=$BT$9,$BT14,IF(AC$8=$BS$9,$BS14,IF(AC$8=$BU$9,$BU14,IF(AC$8=$BV$9,$BV14,IF(AC$8=$BW$9,$BW14,IF(AC$8=$BX$9,$BX14,IF(AC$8=$BY$9,$BY14,IF(AC$8=$BZ$9,$BZ14,IF(AC$8=$CA$9,$CA14,IF(AC$8=$CC$9,$CC14,IF(AC$8=$CD$9,$CD14,IF(AC$8=$CE$9,$CE14,IF(AC$8=$CF$9,$CF14,IF(AC$8=$CG$9,$CG14,IF(AC$8=$CH$9,$CH14,IF(AC$8=$CI$9,$CI14,IF(AC$8=$CJ$9,$CJ14,IF(AC$8=$CK$9,$CK14,IF(AC$8=$CL$9,$CL14,IF(AC$8=$CM$9,$CM14,IF(AC$8=$CN$9,$CN14,IF(AC$8=$CO$9,$CO14,IF(AC$8=$CP$9,$CP14,IF(AC$8=$CQ$9,$CQ14,"НЕТ")))))))))))))))))))))))) -> ДА | AD14: =IF(AC14="НЕТ","Не требуется",$CR14) -> Не требуется | AF14: =IF(AF$8=$BT$9,$BT14,IF(AF$8=$BS$9,$BS14,IF(AF$8=$BU$9,$BU14,IF(AF$8=$BV$9,$BV14,IF(AF$8=$BW$9,$BW14,IF(AF$8=$BX$9,$BX14,IF(AF$8=$BY$9,$BY14,IF(AF$8=$BZ$9,$BZ14,IF(AF$8=$CA$9,$CA14,IF(AF$8=$CC$9,$CC14,IF(AF$8=$CD$9,$CD14,IF(AF$8=$CE$9,$CE14,IF(AF$8=$CF$9,$CF14,IF(AF$8=$CG$9,$CG14,IF(AF$8=$CH$9,$CH14,IF(AF$8=$CI$9,$CI14,IF(AF$8=$CJ$9,$CJ14,IF(AF$8=$CK$9,$CK14,IF(AF$8=$CL$9,$CL14,IF(AF$8=$CM$9,$CM14,IF(AF$8=$CN$9,$CN14,IF(AF$8=$CO$9,$CO14,IF(AF$8=$CP$9,$CP14,IF(AF$8=$CQ$9,$CQ14,"НЕТ")))))))))))))))))))))))) -> ДА | AG14: =IF(AG$8=$BT$9,$BT14,IF(AG$8=$BS$9,$BS14,IF(AG$8=$BU$9,$BU14,IF(AG$8=$BV$9,$BV14,IF(AG$8=$BW$9,$BW14,IF(AG$8=$BX$9,$BX14,IF(AG$8=$BY$9,$BY14,IF(AG$8=$BZ$9,$BZ14,IF(AG$8=$CA$9,$CA14,IF(AG$8=$CC$9,$CC14,IF(AG$8=$CD$9,$CD14,IF(AG$8=$CE$9,$CE14,IF(AG$8=$CF$9,$CF14,IF(AG$8=$CG$9,$CG14,IF(AG$8=$CH$9,$CH14,IF(AG$8=$CI$9,$CI14,IF(AG$8=$CJ$9,$CJ14,IF(AG$8=$CK$9,$CK14,IF(AG$8=$CL$9,$CL14,IF(AG$8=$CM$9,$CM14,IF(AG$8=$CN$9,$CN14,IF(AG$8=$CO$9,$CO14,IF(AG$8=$CP$9,$CP14,IF(AG$8=$CQ$9,$CQ14,"НЕТ")))))))))))))))))))))))) -> НЕТ | AH14: =IF(AH$8=$BT$9,$BT14,IF(AH$8=$BS$9,$BS14,IF(AH$8=$BU$9,$BU14,IF(AH$8=$BV$9,$BV14,IF(AH$8=$BW$9,$BW14,IF(AH$8=$BX$9,$BX14,IF(AH$8=$BY$9,$BY14,IF(AH$8=$BZ$9,$BZ14,IF(AH$8=$CA$9,$CA14,IF(AH$8=$CC$9,$CC14,IF(AH$8=$CD$9,$CD14,IF(AH$8=$CE$9,$CE14,IF(AH$8=$CF$9,$CF14,IF(AH$8=$CG$9,$CG14,IF(AH$8=$CH$9,$CH14,IF(AH$8=$CI$9,$CI14,IF(AH$8=$CJ$9,$CJ14,IF(AH$8=$CK$9,$CK14,IF(AH$8=$CL$9,$CL14,IF(AH$8=$CM$9,$CM14,IF(AH$8=$CN$9,$CN14,IF(AH$8=$CO$9,$CO14,IF(AH$8=$CP$9,$CP14,IF(AH$8=$CQ$9,$CQ14,"НЕТ")))))))))))))))))))))))) -> НЕТ | AI14: =IF(AI$8=$BT$9,$BT14,IF(AI$8=$BS$9,$BS14,IF(AI$8=$BU$9,$BU14,IF(AI$8=$BV$9,$BV14,IF(AI$8=$BW$9,$BW14,IF(AI$8=$BX$9,$BX14,IF(AI$8=$BY$9,$BY14,IF(AI$8=$BZ$9,$BZ14,IF(AI$8=$CA$9,$CA14,IF(AI$8=$CC$9,$CC14,IF(AI$8=$CD$9,$CD14,IF(AI$8=$CE$9,$CE14,IF(AI$8=$CF$9,$CF14,IF(AI$8=$CG$9,$CG14,IF(AI$8=$CH$9,$CH14,IF(AI$8=$CI$9,$CI14,IF(AI$8=$CJ$9,$CJ14,IF(AI$8=$CK$9,$CK14,IF(AI$8=$CL$9,$CL14,IF(AI$8=$CM$9,$CM14,IF(AI$8=$CN$9,$CN14,IF(AI$8=$CO$9,$CO14,IF(AI$8=$CP$9,$CP14,IF(AI$8=$CQ$9,$CQ14,"НЕТ")))))))))))))))))))))))) -> НЕТ | AJ14: =IF(AJ$8=$BT$9,$BT14,IF(AJ$8=$BS$9,$BS14,IF(AJ$8=$BU$9,$BU14,IF(AJ$8=$BV$9,$BV14,IF(AJ$8=$BW$9,$BW14,IF(AJ$8=$BX$9,$BX14,IF(AJ$8=$BY$9,$BY14,IF(AJ$8=$BZ$9,$BZ14,IF(AJ$8=$CA$9,$CA14,IF(AJ$8=$CC$9,$CC14,IF(AJ$8=$CD$9,$CD14,IF(AJ$8=$CE$9,$CE14,IF(AJ$8=$CF$9,$CF14,IF(AJ$8=$CG$9,$CG14,IF(AJ$8=$CH$9,$CH14,IF(AJ$8=$CI$9,$CI14,IF(AJ$8=$CJ$9,$CJ14,IF(AJ$8=$CK$9,$CK14,IF(AJ$8=$CL$9,$CL14,IF(AJ$8=$CM$9,$CM14,IF(AJ$8=$CN$9,$CN14,IF(AJ$8=$CO$9,$CO14,IF(AJ$8=$CP$9,$CP14,IF(AJ$8=$CQ$9,$CQ14,"НЕТ")))))))))))))))))))))))) -> НЕТ | AK14: =IF(AK$8=$BT$9,$BT14,IF(AK$8=$BS$9,$BS14,IF(AK$8=$BU$9,$BU14,IF(AK$8=$BV$9,$BV14,IF(AK$8=$BW$9,$BW14,IF(AK$8=$BX$9,$BX14,IF(AK$8=$BY$9,$BY14,IF(AK$8=$BZ$9,$BZ14,IF(AK$8=$CA$9,$CA14,IF(AK$8=$CC$9,$CC14,IF(AK$8=$CD$9,$CD14,IF(AK$8=$CE$9,$CE14,IF(AK$8=$CF$9,$CF14,IF(AK$8=$CG$9,$CG14,IF(AK$8=$CH$9,$CH14,IF(AK$8=$CI$9,$CI14,IF(AK$8=$CJ$9,$CJ14,IF(AK$8=$CK$9,$CK14,IF(AK$8=$CL$9,$CL14,IF(AK$8=$CM$9,$CM14,IF(AK$8=$CN$9,$CN14,IF(AK$8=$CO$9,$CO14,IF(AK$8=$CP$9,$CP14,IF(AK$8=$CQ$9,$CQ14,"НЕТ")))))))))))))))))))))))) -> НЕТ | AL14: =IF(AL$8=$BT$9,$BT14,IF(AL$8=$BS$9,$BS14,IF(AL$8=$BU$9,$BU14,IF(AL$8=$BV$9,$BV14,IF(AL$8=$BW$9,$BW14,IF(AL$8=$BX$9,$BX14,IF(AL$8=$BY$9,$BY14,IF(AL$8=$BZ$9,$BZ14,IF(AL$8=$CA$9,$CA14,IF(AL$8=$CC$9,$CC14,IF(AL$8=$CD$9,$CD14,IF(AL$8=$CE$9,$CE14,IF(AL$8=$CF$9,$CF14,IF(AL$8=$CG$9,$CG14,IF(AL$8=$CH$9,$CH14,IF(AL$8=$CI$9,$CI14,IF(AL$8=$CJ$9,$CJ14,IF(AL$8=$CK$9,$CK14,IF(AL$8=$CL$9,$CL14,IF(AL$8=$CM$9,$CM14,IF(AL$8=$CN$9,$CN14,IF(AL$8=$CO$9,$CO14,IF(AL$8=$CP$9,$CP14,IF(AL$8=$CQ$9,$CQ14,"НЕТ")))))))))))))))))))))))) -> НЕТ | AM14: =IF(AL14="НЕТ","Не требуется",$CR14) -> Не требуется | AS14: =IF(BS14="ДА",$M14,"") -> 1 | AT14: =IF(BT14="ДА",$M14,"") -> 1 | AU14: =IF(BU14="ДА",$M14,"") -> 1 | AV14: =IF(BV14="ДА",$M14,"") | AW14: =IF(BX14="ДА",$M14,"") -> 1 | AX14: =IF(BY14="ДА",$M14,"") -> 1 | AY14: =IF(BZ14="ДА",$M14,"") -> 1 | AZ14: =IF(CA14="ДА",$M14,"") -> 1 | BB14: =IF(CC14="ДА",$M14,"") -> 1 | BC14: =IF(CD14="ДА",$M14,"") -> 1 | BD14: =IF(CE14="ДА",$M14,"") -> 1 | BE14: =IF(CF14="ДА",$M14,"") -> 1 | BF14: =IF(CG14="ДА",$M14,"") | BG14: =IF(CH14="ДА",$M14,"") -> 1 | BH14: =IF(CI14="ДА",$M14,"") -> 1 | BI14: =IF(CJ14="ДА",$M14,"") | ... BP14: =IF(CQ14="ДА",$M14,"") | BS14: ДА | BT14: ДА | BU14: ДА | BV14: НЕТ | BW14: ДА | BX14: ДА | BY14: ДА | BZ14: ДА | CA14: ДА | CC14: ДА | CD14: ДА | CE14: ДА | CF14: ДА | CG14: НЕТ | CH14: ДА | CI14: ДА | CJ14: НЕТ | CK14: ДА | CL14: ДА | CM14: ДА | CN14: НЕТ | CO14: НЕТ | CP14: НЕТ | CQ14: НЕТ | CR14: Не требуется
B15: Анализ загрузки подразделений и специальностей по задачам производственной программы | C15: Как в РМ4 нет, но есть табличный редактор. Текущая реализация - очень неудобная. Технология ПРОФ-мини. С помощью настройки табличного редактора (выбрав подразделение операции или ресурса) | N15: =SUM(O15,R15,U15,X15) -> 0
B16: Ручное выравнивание загрузки подразделений по задачам портфеля проектов в т.ч. С помощью документа "Прогноз трудозатрат по ролям" | C16: Как в РМ4 нет, но есть табличный редактор. Текущая реализация - очень неудобная. Технология ПРОФ-мини. С помощью настройки табличного редактора (выбрав подразделение операции или ресурса) | N16: =SUM(O16,R16,U16,X16) -> 0
A17: 1.3. | B17: Расчет цены контракта (Возможно включение в Кейс с увеличением стоимости) Нужно зафиксировать сценарий в материалах Кейса | C17: Нет | F17: Проф | G17: Проф/мини | H17: Нет | I17: Нет | J17: Да | K17: Да | L17: Под проект | M17: 2 | N17: =SUM(O17,R17,U17,X17) -> 2 | O17: =IF(AC17="ДА",$M17,"") | Q17: =IF(AC17="ДА",ROUNDUP(O17/5,0),0) -> 0 | R17: =IF(AF17="ДА",$M17,"") -> 2 | T17: =IF(AF17="ДА",ROUNDUP(R17/5,0),0) -> 1 | U17: =IF(AI17="ДА",$M17,"") | W17: =IF(AI17="ДА",ROUNDUP(U17/5,0),0) -> 0 | X17: =IF(AL17="ДА",$M17,"") | Z17: =IF(AL17="ДА",ROUNDUP(X17/5,0),0) -> 0 | AA17: =IF(OR(AC17="ДА",AF17="ДА",AI17="ДА",AL17="ДА"),"ДА","НЕТ") -> ДА | AC17: =IF(AC$8=$BT$9,$BT17,IF(AC$8=$BS$9,$BS17,IF(AC$8=$BU$9,$BU17,IF(AC$8=$BV$9,$BV17,IF(AC$8=$BW$9,$BW17,IF(AC$8=$BX$9,$BX17,IF(AC$8=$BY$9,$BY17,IF(AC$8=$BZ$9,$BZ17,IF(AC$8=$CA$9,$CA17,IF(AC$8=$CC$9,$CC17,IF(AC$8=$CD$9,$CD17,IF(AC$8=$CE$9,$CE17,IF(AC$8=$CF$9,$CF17,IF(AC$8=$CG$9,$CG17,IF(AC$8=$CH$9,$CH17,IF(AC$8=$CI$9,$CI17,IF(AC$8=$CJ$9,$CJ17,IF(AC$8=$CK$9,$CK17,IF(AC$8=$CL$9,$CL17,IF(AC$8=$CM$9,$CM17,IF(AC$8=$CN$9,$CN17,IF(AC$8=$CO$9,$CO17,IF(AC$8=$CP$9,$CP17,IF(AC$8=$CQ$9,$CQ17,"НЕТ")))))))))))))))))))))))) -> НЕТ | AD17: =IF(AC17="НЕТ","Не требуется",$CR17) -> Не требуется | AF17: =IF(AF$8=$BT$9,$BT17,IF(AF$8=$BS$9,$BS17,IF(AF$8=$BU$9,$BU17,IF(AF$8=$BV$9,$BV17,IF(AF$8=$BW$9,$BW17,IF(AF$8=$BX$9,$BX17,IF(AF$8=$BY$9,$BY17,IF(AF$8=$BZ$9,$BZ17,IF(AF$8=$CA$9,$CA17,IF(AF$8=$CC$9,$CC17,IF(AF$8=$CD$9,$CD17,IF(AF$8=$CE$9,$CE17,IF(AF$8=$CF$9,$CF17,IF(AF$8=$CG$9,$CG17,IF(AF$8=$CH$9,$CH17,IF(AF$8=$CI$9,$CI17,IF(AF$8=$CJ$9,$CJ17,IF(AF$8=$CK$9,$CK17,IF(AF$8=$CL$9,$CL17,IF(AF$8=$CM$9,$CM17,IF(AF$8=$CN$9,$CN17,IF(AF$8=$CO$9,$CO17,IF(AF$8=$CP$9,$CP17,IF(AF$8=$CQ$9,$CQ17,"НЕТ")))))))))))))))))))))))) -> ДА | AG17: =IF(AG$8=$BT$9,$BT17,IF(AG$8=$BS$9,$BS17,IF(AG$8=$BU$9,$BU17,IF(AG$8=$BV$9,$BV17,IF(AG$8=$BW$9,$BW17,IF(AG$8=$BX$9,$BX17,IF(AG$8=$BY$9,$BY17,IF(AG$8=$BZ$9,$BZ17,IF(AG$8=$CA$9,$CA17,IF(AG$8=$CC$9,$CC17,IF(AG$8=$CD$9,$CD17,IF(AG$8=$CE$9,$CE17,IF(AG$8=$CF$9,$CF17,IF(AG$8=$CG$9,$CG17,IF(AG$8=$CH$9,$CH17,IF(AG$8=$CI$9,$CI17,IF(AG$8=$CJ$9,$CJ17,IF(AG$8=$CK$9,$CK17,IF(AG$8=$CL$9,$CL17,IF(AG$8=$CM$9,$CM17,IF(AG$8=$CN$9,$CN17,IF(AG$8=$CO$9,$CO17,IF(AG$8=$CP$9,$CP17,IF(AG$8=$CQ$9,$CQ17,"НЕТ")))))))))))))))))))))))) -> НЕТ | AH17: =IF(AH$8=$BT$9,$BT17,IF(AH$8=$BS$9,$BS17,IF(AH$8=$BU$9,$BU17,IF(AH$8=$BV$9,$BV17,IF(AH$8=$BW$9,$BW17,IF(AH$8=$BX$9,$BX17,IF(AH$8=$BY$9,$BY17,IF(AH$8=$BZ$9,$BZ17,IF(AH$8=$CA$9,$CA17,IF(AH$8=$CC$9,$CC17,IF(AH$8=$CD$9,$CD17,IF(AH$8=$CE$9,$CE17,IF(AH$8=$CF$9,$CF17,IF(AH$8=$CG$9,$CG17,IF(AH$8=$CH$9,$CH17,IF(AH$8=$CI$9,$CI17,IF(AH$8=$CJ$9,$CJ17,IF(AH$8=$CK$9,$CK17,IF(AH$8=$CL$9,$CL17,IF(AH$8=$CM$9,$CM17,IF(AH$8=$CN$9,$CN17,IF(AH$8=$CO$9,$CO17,IF(AH$8=$CP$9,$CP17,IF(AH$8=$CQ$9,$CQ17,"НЕТ")))))))))))))))))))))))) -> НЕТ | AI17: =IF(AI$8=$BT$9,$BT17,IF(AI$8=$BS$9,$BS17,IF(AI$8=$BU$9,$BU17,IF(AI$8=$BV$9,$BV17,IF(AI$8=$BW$9,$BW17,IF(AI$8=$BX$9,$BX17,IF(AI$8=$BY$9,$BY17,IF(AI$8=$BZ$9,$BZ17,IF(AI$8=$CA$9,$CA17,IF(AI$8=$CC$9,$CC17,IF(AI$8=$CD$9,$CD17,IF(AI$8=$CE$9,$CE17,IF(AI$8=$CF$9,$CF17,IF(AI$8=$CG$9,$CG17,IF(AI$8=$CH$9,$CH17,IF(AI$8=$CI$9,$CI17,IF(AI$8=$CJ$9,$CJ17,IF(AI$8=$CK$9,$CK17,IF(AI$8=$CL$9,$CL17,IF(AI$8=$CM$9,$CM17,IF(AI$8=$CN$9,$CN17,IF(AI$8=$CO$9,$CO17,IF(AI$8=$CP$9,$CP17,IF(AI$8=$CQ$9,$CQ17,"НЕТ")))))))))))))))))))))))) -> НЕТ | AJ17: =IF(AJ$8=$BT$9,$BT17,IF(AJ$8=$BS$9,$BS17,IF(AJ$8=$BU$9,$BU17,IF(AJ$8=$BV$9,$BV17,IF(AJ$8=$BW$9,$BW17,IF(AJ$8=$BX$9,$BX17,IF(AJ$8=$BY$9,$BY17,IF(AJ$8=$BZ$9,$BZ17,IF(AJ$8=$CA$9,$CA17,IF(AJ$8=$CC$9,$CC17,IF(AJ$8=$CD$9,$CD17,IF(AJ$8=$CE$9,$CE17,IF(AJ$8=$CF$9,$CF17,IF(AJ$8=$CG$9,$CG17,IF(AJ$8=$CH$9,$CH17,IF(AJ$8=$CI$9,$CI17,IF(AJ$8=$CJ$9,$CJ17,IF(AJ$8=$CK$9,$CK17,IF(AJ$8=$CL$9,$CL17,IF(AJ$8=$CM$9,$CM17,IF(AJ$8=$CN$9,$CN17,IF(AJ$8=$CO$9,$CO17,IF(AJ$8=$CP$9,$CP17,IF(AJ$8=$CQ$9,$CQ17,"НЕТ")))))))))))))))))))))))) -> НЕТ | AK17: =IF(AK$8=$BT$9,$BT17,IF(AK$8=$BS$9,$BS17,IF(AK$8=$BU$9,$BU17,IF(AK$8=$BV$9,$BV17,IF(AK$8=$BW$9,$BW17,IF(AK$8=$BX$9,$BX17,IF(AK$8=$BY$9,$BY17,IF(AK$8=$BZ$9,$BZ17,IF(AK$8=$CA$9,$CA17,IF(AK$8=$CC$9,$CC17,IF(AK$8=$CD$9,$CD17,IF(AK$8=$CE$9,$CE17,IF(AK$8=$CF$9,$CF17,IF(AK$8=$CG$9,$CG17,IF(AK$8=$CH$9,$CH17,IF(AK$8=$CI$9,$CI17,IF(AK$8=$CJ$9,$CJ17,IF(AK$8=$CK$9,$CK17,IF(AK$8=$CL$9,$CL17,IF(AK$8=$CM$9,$CM17,IF(AK$8=$CN$9,$CN17,IF(AK$8=$CO$9,$CO17,IF(AK$8=$CP$9,$CP17,IF(AK$8=$CQ$9,$CQ17,"НЕТ")))))))))))))))))))))))) -> НЕТ | AL17: =IF(AL$8=$BT$9,$BT17,IF(AL$8=$BS$9,$BS17,IF(AL$8=$BU$9,$BU17,IF(AL$8=$BV$9,$BV17,IF(AL$8=$BW$9,$BW17,IF(AL$8=$BX$9,$BX17,IF(AL$8=$BY$9,$BY17,IF(AL$8=$BZ$9,$BZ17,IF(AL$8=$CA$9,$CA17,IF(AL$8=$CC$9,$CC17,IF(AL$8=$CD$9,$CD17,IF(AL$8=$CE$9,$CE17,IF(AL$8=$CF$9,$CF17,IF(AL$8=$CG$9,$CG17,IF(AL$8=$CH$9,$CH17,IF(AL$8=$CI$9,$CI17,IF(AL$8=$CJ$9,$CJ17,IF(AL$8=$CK$9,$CK17,IF(AL$8=$CL$9,$CL17,IF(AL$8=$CM$9,$CM17,IF(AL$8=$CN$9,$CN17,IF(AL$8=$CO$9,$CO17,IF(AL$8=$CP$9,$CP17,IF(AL$8=$CQ$9,$CQ17,"НЕТ")))))))))))))))))))))))) -> НЕТ | AM17: =IF(AL17="НЕТ","Не требуется",$CR17) -> Не требуется | AS17: =IF(BT17="ДА",$M17,"") | AT17: =IF(BU17="ДА",$M17,"") | AU17: =IF(BV17="ДА",$M17,"") | AV17: =IF(BW17="ДА",$M17,"") | AW17: =IF(BX17="ДА",$M17,"") -> 2 | AX17: =IF(BY17="ДА",$M17,"") -> 2 | AY17: =IF(BZ17="ДА",$M17,"") -> 2 | AZ17: =IF(CA17="ДА",$M17,"") -> 2 | BB17: =IF(CC17="ДА",$M17,"") | BC17: =IF(CD17="ДА",$M17,"") | BD17: =IF(CE17="ДА",$M17,"") | BE17: =IF(CF17="ДА",$M17,"") | BF17: =IF(CG17="ДА",$M17,"") | BG17: =IF(CH17="ДА",$M17,"") | BH17: =IF(CI17="ДА",$M17,"") | BI17: =IF(CJ17="ДА",$M17,"") | ... BP17: =IF(CQ17="ДА",$M17,"") | BS17: НЕТ | BT17: НЕТ | BU17: НЕТ | BV17: НЕТ | BW17: НЕТ | BX17: ДА | BY17: ДА | BZ17: ДА | CA17: ДА | CC17: НЕТ | CD17: НЕТ | CE17: НЕТ | CF17: НЕТ | CG17: НЕТ | CH17: НЕТ | CI17: НЕТ | CJ17: НЕТ | CK17: НЕТ | CL17: НЕТ | CM17: ДА | CN17: НЕТ | CO17: НЕТ | CP17: НЕТ | CQ17: НЕТ | CR17: Предоставляется Заказчиком
B18: Расчет цены контракта | C18: Нет | N18: =SUM(O18,R18,U18,X18) -> 0
B19: Планирование и мониторинг процесса продажи как проекта | C19: Нет | N19: =SUM(O19,R19,U19,X19) -> 0
A20: 1.4. | B20: Моделирование инвест. портфеля. Ранжирование заявок на проекты. | C20: Нет | F20: Проф | G20: КОРП-проект | H20: Нет | I20: Нет | J20: Да | K20: Да | L20: Под проект | M20: 8 | N20: =SUM(O20,R20,U20,X20) -> 8 | O20: =IF(AC20="ДА",$M20,"") | Q20: =IF(AC20="ДА",ROUNDUP(O20/5,0),0) -> 0 | R20: =IF(AF20="ДА",$M20,"") -> 8 | T20: =IF(AF20="ДА",ROUNDUP(R20/5,0),0) -> 2 | U20: =IF(AI20="ДА",$M20,"") | W20: =IF(AI20="ДА",ROUNDUP(U20/5,0),0) -> 0 | X20: =IF(AL20="ДА",$M20,"") | Z20: =IF(AL20="ДА",ROUNDUP(X20/5,0),0) -> 0 | AA20: =IF(OR(AC20="ДА",AF20="ДА",AI20="ДА",AL20="ДА"),"ДА","НЕТ") -> ДА | AC20: =IF(AC$8=$BT$9,$BT20,IF(AC$8=$BS$9,$BS20,IF(AC$8=$BU$9,$BU20,IF(AC$8=$BV$9,$BV20,IF(AC$8=$BW$9,$BW20,IF(AC$8=$BX$9,$BX20,IF(AC$8=$BY$9,$BY20,IF(AC$8=$BZ$9,$BZ20,IF(AC$8=$CA$9,$CA20,IF(AC$8=$CC$9,$CC20,IF(AC$8=$CD$9,$CD20,IF(AC$8=$CE$9,$CE20,IF(AC$8=$CF$9,$CF20,IF(AC$8=$CG$9,$CG20,IF(AC$8=$CH$9,$CH20,IF(AC$8=$CI$9,$CI20,IF(AC$8=$CJ$9,$CJ20,IF(AC$8=$CK$9,$CK20,IF(AC$8=$CL$9,$CL20,IF(AC$8=$CM$9,$CM20,IF(AC$8=$CN$9,$CN20,IF(AC$8=$CO$9,$CO20,IF(AC$8=$CP$9,$CP20,IF(AC$8=$CQ$9,$CQ20,"НЕТ")))))))))))))))))))))))) -> НЕТ | AD20: =IF(AC20="НЕТ","Не требуется",$CR20) -> Не требуется | AF20: =IF(AF$8=$BT$9,$BT20,IF(AF$8=$BS$9,$BS20,IF(AF$8=$BU$9,$BU20,IF(AF$8=$BV$9,$BV20,IF(AF$8=$BW$9,$BW20,IF(AF$8=$BX$9,$BX20,IF(AF$8=$BY$9,$BY20,IF(AF$8=$BZ$9,$BZ20,IF(AF$8=$CA$9,$CA20,IF(AF$8=$CC$9,$CC20,IF(AF$8=$CD$9,$CD20,IF(AF$8=$CE$9,$CE20,IF(AF$8=$CF$9,$CF20,IF(AF$8=$CG$9,$CG20,IF(AF$8=$CH$9,$CH20,IF(AF$8=$CI$9,$CI20,IF(AF$8=$CJ$9,$CJ20,IF(AF$8=$CK$9,$CK20,IF(AF$8=$CL$9,$CL20,IF(AF$8=$CM$9,$CM20,IF(AF$8=$CN$9,$CN20,IF(AF$8=$CO$9,$CO20,IF(AF$8=$CP$9,$CP20,IF(AF$8=$CQ$9,$CQ20,"НЕТ")))))))))))))))))))))))) -> ДА | AG20: =IF(AG$8=$BT$9,$BT20,IF(AG$8=$BS$9,$BS20,IF(AG$8=$BU$9,$BU20,IF(AG$8=$BV$9,$BV20,IF(AG$8=$BW$9,$BW20,IF(AG$8=$BX$9,$BX20,IF(AG$8=$BY$9,$BY20,IF(AG$8=$BZ$9,$BZ20,IF(AG$8=$CA$9,$CA20,IF(AG$8=$CC$9,$CC20,IF(AG$8=$CD$9,$CD20,IF(AG$8=$CE$9,$CE20,IF(AG$8=$CF$9,$CF20,IF(AG$8=$CG$9,$CG20,IF(AG$8=$CH$9,$CH20,IF(AG$8=$CI$9,$CI20,IF(AG$8=$CJ$9,$CJ20,IF(AG$8=$CK$9,$CK20,IF(AG$8=$CL$9,$CL20,IF(AG$8=$CM$9,$CM20,IF(AG$8=$CN$9,$CN20,IF(AG$8=$CO$9,$CO20,IF(AG$8=$CP$9,$CP20,IF(AG$8=$CQ$9,$CQ20,"НЕТ")))))))))))))))))))))))) -> НЕТ | AH20: =IF(AH$8=$BT$9,$BT20,IF(AH$8=$BS$9,$BS20,IF(AH$8=$BU$9,$BU20,IF(AH$8=$BV$9,$BV20,IF(AH$8=$BW$9,$BW20,IF(AH$8=$BX$9,$BX20,IF(AH$8=$BY$9,$BY20,IF(AH$8=$BZ$9,$BZ20,IF(AH$8=$CA$9,$CA20,IF(AH$8=$CC$9,$CC20,IF(AH$8=$CD$9,$CD20,IF(AH$8=$CE$9,$CE20,IF(AH$8=$CF$9,$CF20,IF(AH$8=$CG$9,$CG20,IF(AH$8=$CH$9,$CH20,IF(AH$8=$CI$9,$CI20,IF(AH$8=$CJ$9,$CJ20,IF(AH$8=$CK$9,$CK20,IF(AH$8=$CL$9,$CL20,IF(AH$8=$CM$9,$CM20,IF(AH$8=$CN$9,$CN20,IF(AH$8=$CO$9,$CO20,IF(AH$8=$CP$9,$CP20,IF(AH$8=$CQ$9,$CQ20,"НЕТ")))))))))))))))))))))))) -> НЕТ | AI20: =IF(AI$8=$BT$9,$BT20,IF(AI$8=$BS$9,$BS20,IF(AI$8=$BU$9,$BU20,IF(AI$8=$BV$9,$BV20,IF(AI$8=$BW$9,$BW20,IF(AI$8=$BX$9,$BX20,IF(AI$8=$BY$9,$BY20,IF(AI$8=$BZ$9,$BZ20,IF(AI$8=$CA$9,$CA20,IF(AI$8=$CC$9,$CC20,IF(AI$8=$CD$9,$CD20,IF(AI$8=$CE$9,$CE20,IF(AI$8=$CF$9,$CF20,IF(AI$8=$CG$9,$CG20,IF(AI$8=$CH$9,$CH20,IF(AI$8=$CI$9,$CI20,IF(AI$8=$CJ$9,$CJ20,IF(AI$8=$CK$9,$CK20,IF(AI$8=$CL$9,$CL20,IF(AI$8=$CM$9,$CM20,IF(AI$8=$CN$9,$CN20,IF(AI$8=$CO$9,$CO20,IF(AI$8=$CP$9,$CP20,IF(AI$8=$CQ$9,$CQ20,"НЕТ")))))))))))))))))))))))) -> НЕТ | AJ20: =IF(AJ$8=$BT$9,$BT20,IF(AJ$8=$BS$9,$BS20,IF(AJ$8=$BU$9,$BU20,IF(AJ$8=$BV$9,$BV20,IF(AJ$8=$BW$9,$BW20,IF(AJ$8=$BX$9,$BX20,IF(AJ$8=$BY$9,$BY20,IF(AJ$8=$BZ$9,$BZ20,IF(AJ$8=$CA$9,$CA20,IF(AJ$8=$CC$9,$CC20,IF(AJ$8=$CD$9,$CD20,IF(AJ$8=$CE$9,$CE20,IF(AJ$8=$CF$9,$CF20,IF(AJ$8=$CG$9,$CG20,IF(AJ$8=$CH$9,$CH20,IF(AJ$8=$CI$9,$CI20,IF(AJ$8=$CJ$9,$CJ20,IF(AJ$8=$CK$9,$CK20,IF(AJ$8=$CL$9,$CL20,IF(AJ$8=$CM$9,$CM20,IF(AJ$8=$CN$9,$CN20,IF(AJ$8=$CO$9,$CO20,IF(AJ$8=$CP$9,$CP20,IF(AJ$8=$CQ$9,$CQ20,"НЕТ")))))))))))))))))))))))) -> НЕТ | AK20: =IF(AK$8=$BT$9,$BT20,IF(AK$8=$BS$9,$BS20,IF(AK$8=$BU$9,$BU20,IF(AK$8=$BV$9,$BV20,IF(AK$8=$BW$9,$BW20,IF(AK$8=$BX$9,$BX20,IF(AK$8=$BY$9,$BY20,IF(AK$8=$BZ$9,$BZ20,IF(AK$8=$CA$9,$CA20,IF(AK$8=$CC$9,$CC20,IF(AK$8=$CD$9,$CD20,IF(AK$8=$CE$9,$CE20,IF(AK$8=$CF$9,$CF20,IF(AK$8=$CG$9,$CG20,IF(AK$8=$CH$9,$CH20,IF(AK$8=$CI$9,$CI20,IF(AK$8=$CJ$9,$CJ20,IF(AK$8=$CK$9,$CK20,IF(AK$8=$CL$9,$CL20,IF(AK$8=$CM$9,$CM20,IF(AK$8=$CN$9,$CN20,IF(AK$8=$CO$9,$CO20,IF(AK$8=$CP$9,$CP20,IF(AK$8=$CQ$9,$CQ20,"НЕТ")))))))))))))))))))))))) -> НЕТ | AL20: =IF(AL$8=$BT$9,$BT20,IF(AL$8=$BS$9,$BS20,IF(AL$8=$BU$9,$BU20,IF(AL$8=$BV$9,$BV20,IF(AL$8=$BW$9,$BW20,IF(AL$8=$BX$9,$BX20,IF(AL$8=$BY$9,$BY20,IF(AL$8=$BZ$9,$BZ20,IF(AL$8=$CA$9,$CA20,IF(AL$8=$CC$9,$CC20,IF(AL$8=$CD$9,$CD20,IF(AL$8=$CE$9,$CE20,IF(AL$8=$CF$9,$CF20,IF(AL$8=$CG$9,$CG20,IF(AL$8=$CH$9,$CH20,IF(AL$8=$CI$9,$CI20,IF(AL$8=$CJ$9,$CJ20,IF(AL$8=$CK$9,$CK20,IF(AL$8=$CL$9,$CL20,IF(AL$8=$CM$9,$CM20,IF(AL$8=$CN$9,$CN20,IF(AL$8=$CO$9,$CO20,IF(AL$8=$CP$9,$CP20,IF(AL$8=$CQ$9,$CQ20,"НЕТ")))))))))))))))))))))))) -> НЕТ | AM20: =IF(AL20="НЕТ","Не требуется",$CR20) -> Не требуется | AS20: =IF(BS20="ДА",$M20,"") | AT20: =IF(BT20="ДА",$M20,"") | AU20: =IF(BU20="ДА",$M20,"") | AV20: =IF(BV20="ДА",$M20,"") | AW20: =IF(BX20="ДА",$M20,"") | AX20: =IF(BY20="ДА",$M20,"") | AY20: =IF(BZ20="ДА",$M20,"") -> 8 | AZ20: =IF(CA20="ДА",$M20,"") -> 8 | BB20: =IF(CC20="ДА",$M20,"") | BC20: =IF(CD20="ДА",$M20,"") | BD20: =IF(CE20="ДА",$M20,"") | BE20: =IF(CF20="ДА",$M20,"") | BF20: =IF(CG20="ДА",$M20,"") | BG20: =IF(CH20="ДА",$M20,"") -> 8 | BH20: =IF(CI20="ДА",$M20,"") -> 8 | BI20: =IF(CJ20="ДА",$M20,"") | ... BP20: =IF(CQ20="ДА",$M20,"") | BS20: НЕТ | BT20: НЕТ | BU20: НЕТ | BV20: НЕТ | BW20: НЕТ | BX20: НЕТ | BY20: НЕТ | BZ20: ДА | CA20: ДА | CC20: НЕТ | CD20: НЕТ | CE20: НЕТ | CF20: НЕТ | CG20: НЕТ | CH20: ДА | CI20: ДА | CJ20: НЕТ | CK20: ДА | CL20: ДА | CM20: НЕТ | CN20: НЕТ | CO20: НЕТ | CP20: НЕТ | CQ20: НЕТ | CR20: Предоставляется Заказчиком
B21: Формирование заявок на проект. Мониторинг состояния заявок. | C21: нет | N21: =SUM(O21,R21,U21,X21) -> 0
B22: Регистрация значений показателей эффективности проектов (Внутренняя ставка доходности, срок окупаемости, индекс прибыльности, чистый денежный поток, чистая приведенная стоимость) | C22: нет | N22: =SUM(O22,R22,U22,X22) -> 0
B23: Оценка соответствия портфеля инвестиционных проектов стратегическим целям компании | C23: нет | N23: =SUM(O23,R23,U23,X23) -> 0
B24: Расчет итогового балла проектов | C24: нет | N24: =SUM(O24,R24,U24,X24) -> 0
B25: Ранжирование проектов по показателям эффективности и формирование бизнес плана по портфелю проектов. | C25: нет | N25: =SUM(O25,R25,U25,X25) -> 0
B26: Формирование портфеля инвестиционных проектов (проекта с компонентой "Портфель проектов") | C26: нет | N26: =SUM(O26,R26,U26,X26) -> 0
A27: 1.5. | B27: Мониторинг договорной кампании | F27: Базовый | G27: Кейс-проект | H27: Да | I27: Да | J27: Да | K27: Да | L27: В разработке | M27: 2 | N27: =SUM(O27,R27,U27,X27) -> 6 | O27: =IF(AC27="ДА",$M27,"") -> 2 | Q27: =IF(AC27="ДА",ROUNDUP(O27/5,0),0) -> 1 | R27: =IF(AF27="ДА",$M27,"") -> 2 | T27: =IF(AF27="ДА",ROUNDUP(R27/5,0),0) -> 1 | U27: =IF(AI27="ДА",$M27,"") -> 2 | W27: =IF(AI27="ДА",ROUNDUP(U27/5,0),0) -> 1 | X27: =IF(AL27="ДА",$M27,"") | Z27: =IF(AL27="ДА",ROUNDUP(X27/5,0),0) -> 0 | AA27: =IF(OR(AC27="ДА",AF27="ДА",AI27="ДА",AL27="ДА"),"ДА","НЕТ") -> ДА | AC27: =IF(AC$8=$BT$9,$BT27,IF(AC$8=$BS$9,$BS27,IF(AC$8=$BU$9,$BU27,IF(AC$8=$BV$9,$BV27,IF(AC$8=$BW$9,$BW27,IF(AC$8=$BX$9,$BX27,IF(AC$8=$BY$9,$BY27,IF(AC$8=$BZ$9,$BZ27,IF(AC$8=$CA$9,$CA27,IF(AC$8=$CC$9,$CC27,IF(AC$8=$CD$9,$CD27,IF(AC$8=$CE$9,$CE27,IF(AC$8=$CF$9,$CF27,IF(AC$8=$CG$9,$CG27,IF(AC$8=$CH$9,$CH27,IF(AC$8=$CI$9,$CI27,IF(AC$8=$CJ$9,$CJ27,IF(AC$8=$CK$9,$CK27,IF(AC$8=$CL$9,$CL27,IF(AC$8=$CM$9,$CM27,IF(AC$8=$CN$9,$CN27,IF(AC$8=$CO$9,$CO27,IF(AC$8=$CP$9,$CP27,IF(AC$8=$CQ$9,$CQ27,"НЕТ")))))))))))))))))))))))) -> ДА | AD27: =IF(AC27="НЕТ","Не требуется",$CR27) -> Предоставляется Заказчиком | AF27: =IF(AF$8=$BT$9,$BT27,IF(AF$8=$BS$9,$BS27,IF(AF$8=$BU$9,$BU27,IF(AF$8=$BV$9,$BV27,IF(AF$8=$BW$9,$BW27,IF(AF$8=$BX$9,$BX27,IF(AF$8=$BY$9,$BY27,IF(AF$8=$BZ$9,$BZ27,IF(AF$8=$CA$9,$CA27,IF(AF$8=$CC$9,$CC27,IF(AF$8=$CD$9,$CD27,IF(AF$8=$CE$9,$CE27,IF(AF$8=$CF$9,$CF27,IF(AF$8=$CG$9,$CG27,IF(AF$8=$CH$9,$CH27,IF(AF$8=$CI$9,$CI27,IF(AF$8=$CJ$9,$CJ27,IF(AF$8=$CK$9,$CK27,IF(AF$8=$CL$9,$CL27,IF(AF$8=$CM$9,$CM27,IF(AF$8=$CN$9,$CN27,IF(AF$8=$CO$9,$CO27,IF(AF$8=$CP$9,$CP27,IF(AF$8=$CQ$9,$CQ27,"НЕТ")))))))))))))))))))))))) -> ДА | AG27: =IF(AG$8=$BT$9,$BT27,IF(AG$8=$BS$9,$BS27,IF(AG$8=$BU$9,$BU27,IF(AG$8=$BV$9,$BV27,IF(AG$8=$BW$9,$BW27,IF(AG$8=$BX$9,$BX27,IF(AG$8=$BY$9,$BY27,IF(AG$8=$BZ$9,$BZ27,IF(AG$8=$CA$9,$CA27,IF(AG$8=$CC$9,$CC27,IF(AG$8=$CD$9,$CD27,IF(AG$8=$CE$9,$CE27,IF(AG$8=$CF$9,$CF27,IF(AG$8=$CG$9,$CG27,IF(AG$8=$CH$9,$CH27,IF(AG$8=$CI$9,$CI27,IF(AG$8=$CJ$9,$CJ27,IF(AG$8=$CK$9,$CK27,IF(AG$8=$CL$9,$CL27,IF(AG$8=$CM$9,$CM27,IF(AG$8=$CN$9,$CN27,IF(AG$8=$CO$9,$CO27,IF(AG$8=$CP$9,$CP27,IF(AG$8=$CQ$9,$CQ27,"НЕТ")))))))))))))))))))))))) -> НЕТ | AH27: =IF(AH$8=$BT$9,$BT27,IF(AH$8=$BS$9,$BS27,IF(AH$8=$BU$9,$BU27,IF(AH$8=$BV$9,$BV27,IF(AH$8=$BW$9,$BW27,IF(AH$8=$BX$9,$BX27,IF(AH$8=$BY$9,$BY27,IF(AH$8=$BZ$9,$BZ27,IF(AH$8=$CA$9,$CA27,IF(AH$8=$CC$9,$CC27,IF(AH$8=$CD$9,$CD27,IF(AH$8=$CE$9,$CE27,IF(AH$8=$CF$9,$CF27,IF(AH$8=$CG$9,$CG27,IF(AH$8=$CH$9,$CH27,IF(AH$8=$CI$9,$CI27,IF(AH$8=$CJ$9,$CJ27,IF(AH$8=$CK$9,$CK27,IF(AH$8=$CL$9,$CL27,IF(AH$8=$CM$9,$CM27,IF(AH$8=$CN$9,$CN27,IF(AH$8=$CO$9,$CO27,IF(AH$8=$CP$9,$CP27,IF(AH$8=$CQ$9,$CQ27,"НЕТ")))))))))))))))))))))))) -> НЕТ | AI27: =IF(AI$8=$BT$9,$BT27,IF(AI$8=$BS$9,$BS27,IF(AI$8=$BU$9,$BU27,IF(AI$8=$BV$9,$BV27,IF(AI$8=$BW$9,$BW27,IF(AI$8=$BX$9,$BX27,IF(AI$8=$BY$9,$BY27,IF(AI$8=$BZ$9,$BZ27,IF(AI$8=$CA$9,$CA27,IF(AI$8=$CC$9,$CC27,IF(AI$8=$CD$9,$CD27,IF(AI$8=$CE$9,$CE27,IF(AI$8=$CF$9,$CF27,IF(AI$8=$CG$9,$CG27,IF(AI$8=$CH$9,$CH27,IF(AI$8=$CI$9,$CI27,IF(AI$8=$CJ$9,$CJ27,IF(AI$8=$CK$9,$CK27,IF(AI$8=$CL$9,$CL27,IF(AI$8=$CM$9,$CM27,IF(AI$8=$CN$9,$CN27,IF(AI$8=$CO$9,$CO27,IF(AI$8=$CP$9,$CP27,IF(AI$8=$CQ$9,$CQ27,"НЕТ")))))))))))))))))))))))) -> ДА | AJ27: =IF(AJ$8=$BT$9,$BT27,IF(AJ$8=$BS$9,$BS27,IF(AJ$8=$BU$9,$BU27,IF(AJ$8=$BV$9,$BV27,IF(AJ$8=$BW$9,$BW27,IF(AJ$8=$BX$9,$BX27,IF(AJ$8=$BY$9,$BY27,IF(AJ$8=$BZ$9,$BZ27,IF(AJ$8=$CA$9,$CA27,IF(AJ$8=$CC$9,$CC27,IF(AJ$8=$CD$9,$CD27,IF(AJ$8=$CE$9,$CE27,IF(AJ$8=$CF$9,$CF27,IF(AJ$8=$CG$9,$CG27,IF(AJ$8=$CH$9,$CH27,IF(AJ$8=$CI$9,$CI27,IF(AJ$8=$CJ$9,$CJ27,IF(AJ$8=$CK$9,$CK27,IF(AJ$8=$CL$9,$CL27,IF(AJ$8=$CM$9,$CM27,IF(AJ$8=$CN$9,$CN27,IF(AJ$8=$CO$9,$CO27,IF(AJ$8=$CP$9,$CP27,IF(AJ$8=$CQ$9,$CQ27,"НЕТ")))))))))))))))))))))))) -> НЕТ | AK27: =IF(AK$8=$BT$9,$BT27,IF(AK$8=$BS$9,$BS27,IF(AK$8=$BU$9,$BU27,IF(AK$8=$BV$9,$BV27,IF(AK$8=$BW$9,$BW27,IF(AK$8=$BX$9,$BX27,IF(AK$8=$BY$9,$BY27,IF(AK$8=$BZ$9,$BZ27,IF(AK$8=$CA$9,$CA27,IF(AK$8=$CC$9,$CC27,IF(AK$8=$CD$9,$CD27,IF(AK$8=$CE$9,$CE27,IF(AK$8=$CF$9,$CF27,IF(AK$8=$CG$9,$CG27,IF(AK$8=$CH$9,$CH27,IF(AK$8=$CI$9,$CI27,IF(AK$8=$CJ$9,$CJ27,IF(AK$8=$CK$9,$CK27,IF(AK$8=$CL$9,$CL27,IF(AK$8=$CM$9,$CM27,IF(AK$8=$CN$9,$CN27,IF(AK$8=$CO$9,$CO27,IF(AK$8=$CP$9,$CP27,IF(AK$8=$CQ$9,$CQ27,"НЕТ")))))))))))))))))))))))) -> НЕТ | AL27: =IF(AL$8=$BT$9,$BT27,IF(AL$8=$BS$9,$BS27,IF(AL$8=$BU$9,$BU27,IF(AL$8=$BV$9,$BV27,IF(AL$8=$BW$9,$BW27,IF(AL$8=$BX$9,$BX27,IF(AL$8=$BY$9,$BY27,IF(AL$8=$BZ$9,$BZ27,IF(AL$8=$CA$9,$CA27,IF(AL$8=$CC$9,$CC27,IF(AL$8=$CD$9,$CD27,IF(AL$8=$CE$9,$CE27,IF(AL$8=$CF$9,$CF27,IF(AL$8=$CG$9,$CG27,IF(AL$8=$CH$9,$CH27,IF(AL$8=$CI$9,$CI27,IF(AL$8=$CJ$9,$CJ27,IF(AL$8=$CK$9,$CK27,IF(AL$8=$CL$9,$CL27,IF(AL$8=$CM$9,$CM27,IF(AL$8=$CN$9,$CN27,IF(AL$8=$CO$9,$CO27,IF(AL$8=$CP$9,$CP27,IF(AL$8=$CQ$9,$CQ27,"НЕТ")))))))))))))))))))))))) -> НЕТ | AM27: =IF(AL27="НЕТ","Не требуется",$CR27) -> Не требуется | AS27: =IF(BS27="ДА",$M27,"") -> 2 | AT27: =IF(BT27="ДА",$M27,"") -> 2 | AU27: =IF(BU27="ДА",$M27,"") -> 2 | AV27: =IF(BV27="ДА",$M27,"") -> 2 | AW27: =IF(BX27="ДА",$M27,"") -> 2 | AX27: =IF(BY27="ДА",$M27,"") -> 2 | AY27: =IF(BZ27="ДА",$M27,"") -> 2 | AZ27: =IF(CA27="ДА",$M27,"") -> 2 | BB27: =IF(CC27="ДА",$M27,"") -> 2 | BC27: =IF(CD27="ДА",$M27,"") -> 2 | BD27: =IF(CE27="ДА",$M27,"") | BE27: =IF(CF27="ДА",$M27,"") | BF27: =IF(CG27="ДА",$M27,"") | BG27: =IF(CH27="ДА",$M27,"") -> 2 | BH27: =IF(CI27="ДА",$M27,"") -> 2 | BI27: =IF(CJ27="ДА",$M27,"") | ... BP27: =IF(CQ27="ДА",$M27,"") | BS27: ДА | BT27: ДА | BU27: ДА | BV27: ДА | BW27: ДА | BX27: ДА | BY27: ДА | BZ27: ДА | CA27: ДА | CC27: ДА | CD27: ДА | CE27: НЕТ | CF27: НЕТ | CG27: НЕТ | CH27: ДА | CI27: ДА | CJ27: НЕТ | CK27: ДА | CL27: НЕТ | CM27: ДА | CN27: НЕТ | CO27: НЕТ | CP27: НЕТ | CQ27: НЕТ | CR27: Предоставляется Заказчиком
B28: Установка статуса договора в карточке договора вручную | C28: не нужно в сценарии. Можно поставить допреквизитом | N28: =SUM(O28,R28,U28,X28) -> 0
B29: Анализ тематического плана | N29: =SUM(O29,R29,U29,X29) -> 0
B30: Хранение файлов и отсканированных копий договора без использования 1С: Документооборот 8 | C30: Можно прикреплять файлы к объектам системы | N30: =SUM(O30,R30,U30,X30) -> 0
A31: 1.6. | B31: Мониторинг фаз проектов портфеля (Gate) | F31: Базовый | G31: Кейс-проект | H31: Нет | I31: Нет | J31: Да | K31: Да | L31: В разработке | M31: 1 | N31: =SUM(O31,R31,U31,X31) -> 1 | O31: =IF(AC31="ДА",$M31,"") | Q31: =IF(AC31="ДА",ROUNDUP(O31/5,0),0) -> 0 | R31: =IF(AF31="ДА",$M31,"") -> 1 | T31: =IF(AF31="ДА",ROUNDUP(R31/5,0),0) -> 1 | U31: =IF(AI31="ДА",$M31,"") | W31: =IF(AI31="ДА",ROUNDUP(U31/5,0),0) -> 0 | X31: =IF(AL31="ДА",$M31,"") | Z31: =IF(AL31="ДА",ROUNDUP(X31/5,0),0) -> 0 | AA31: =IF(OR(AC31="ДА",AF31="ДА",AI31="ДА",AL31="ДА"),"ДА","НЕТ") -> ДА | AC31: =IF(AC$8=$BT$9,$BT31,IF(AC$8=$BS$9,$BS31,IF(AC$8=$BU$9,$BU31,IF(AC$8=$BV$9,$BV31,IF(AC$8=$BW$9,$BW31,IF(AC$8=$BX$9,$BX31,IF(AC$8=$BY$9,$BY31,IF(AC$8=$BZ$9,$BZ31,IF(AC$8=$CA$9,$CA31,IF(AC$8=$CC$9,$CC31,IF(AC$8=$CD$9,$CD31,IF(AC$8=$CE$9,$CE31,IF(AC$8=$CF$9,$CF31,IF(AC$8=$CG$9,$CG31,IF(AC$8=$CH$9,$CH31,IF(AC$8=$CI$9,$CI31,IF(AC$8=$CJ$9,$CJ31,IF(AC$8=$CK$9,$CK31,IF(AC$8=$CL$9,$CL31,IF(AC$8=$CM$9,$CM31,IF(AC$8=$CN$9,$CN31,IF(AC$8=$CO$9,$CO31,IF(AC$8=$CP$9,$CP31,IF(AC$8=$CQ$9,$CQ31,"НЕТ")))))))))))))))))))))))) -> НЕТ | AD31: =IF(AC31="НЕТ","Не требуется",$CR31) -> Не требуется | AF31: =IF(AF$8=$BT$9,$BT31,IF(AF$8=$BS$9,$BS31,IF(AF$8=$BU$9,$BU31,IF(AF$8=$BV$9,$BV31,IF(AF$8=$BW$9,$BW31,IF(AF$8=$BX$9,$BX31,IF(AF$8=$BY$9,$BY31,IF(AF$8=$BZ$9,$BZ31,IF(AF$8=$CA$9,$CA31,IF(AF$8=$CC$9,$CC31,IF(AF$8=$CD$9,$CD31,IF(AF$8=$CE$9,$CE31,IF(AF$8=$CF$9,$CF31,IF(AF$8=$CG$9,$CG31,IF(AF$8=$CH$9,$CH31,IF(AF$8=$CI$9,$CI31,IF(AF$8=$CJ$9,$CJ31,IF(AF$8=$CK$9,$CK31,IF(AF$8=$CL$9,$CL31,IF(AF$8=$CM$9,$CM31,IF(AF$8=$CN$9,$CN31,IF(AF$8=$CO$9,$CO31,IF(AF$8=$CP$9,$CP31,IF(AF$8=$CQ$9,$CQ31,"НЕТ")))))))))))))))))))))))) -> ДА | AG31: =IF(AG$8=$BT$9,$BT31,IF(AG$8=$BS$9,$BS31,IF(AG$8=$BU$9,$BU31,IF(AG$8=$BV$9,$BV31,IF(AG$8=$BW$9,$BW31,IF(AG$8=$BX$9,$BX31,IF(AG$8=$BY$9,$BY31,IF(AG$8=$BZ$9,$BZ31,IF(AG$8=$CA$9,$CA31,IF(AG$8=$CC$9,$CC31,IF(AG$8=$CD$9,$CD31,IF(AG$8=$CE$9,$CE31,IF(AG$8=$CF$9,$CF31,IF(AG$8=$CG$9,$CG31,IF(AG$8=$CH$9,$CH31,IF(AG$8=$CI$9,$CI31,IF(AG$8=$CJ$9,$CJ31,IF(AG$8=$CK$9,$CK31,IF(AG$8=$CL$9,$CL31,IF(AG$8=$CM$9,$CM31,IF(AG$8=$CN$9,$CN31,IF(AG$8=$CO$9,$CO31,IF(AG$8=$CP$9,$CP31,IF(AG$8=$CQ$9,$CQ31,"НЕТ")))))))))))))))))))))))) -> НЕТ | AH31: =IF(AH$8=$BT$9,$BT31,IF(AH$8=$BS$9,$BS31,IF(AH$8=$BU$9,$BU31,IF(AH$8=$BV$9,$BV31,IF(AH$8=$BW$9,$BW31,IF(AH$8=$BX$9,$BX31,IF(AH$8=$BY$9,$BY31,IF(AH$8=$BZ$9,$BZ31,IF(AH$8=$CA$9,$CA31,IF(AH$8=$CC$9,$CC31,IF(AH$8=$CD$9,$CD31,IF(AH$8=$CE$9,$CE31,IF(AH$8=$CF$9,$CF31,IF(AH$8=$CG$9,$CG31,IF(AH$8=$CH$9,$CH31,IF(AH$8=$CI$9,$CI31,IF(AH$8=$CJ$9,$CJ31,IF(AH$8=$CK$9,$CK31,IF(AH$8=$CL$9,$CL31,IF(AH$8=$CM$9,$CM31,IF(AH$8=$CN$9,$CN31,IF(AH$8=$CO$9,$CO31,IF(AH$8=$CP$9,$CP31,IF(AH$8=$CQ$9,$CQ31,"НЕТ")))))))))))))))))))))))) -> НЕТ | AI31: =IF(AI$8=$BT$9,$BT31,IF(AI$8=$BS$9,$BS31,IF(AI$8=$BU$9,$BU31,IF(AI$8=$BV$9,$BV31,IF(AI$8=$BW$9,$BW31,IF(AI$8=$BX$9,$BX31,IF(AI$8=$BY$9,$BY31,IF(AI$8=$BZ$9,$BZ31,IF(AI$8=$CA$9,$CA31,IF(AI$8=$CC$9,$CC31,IF(AI$8=$CD$9,$CD31,IF(AI$8=$CE$9,$CE31,IF(AI$8=$CF$9,$CF31,IF(AI$8=$CG$9,$CG31,IF(AI$8=$CH$9,$CH31,IF(AI$8=$CI$9,$CI31,IF(AI$8=$CJ$9,$CJ31,IF(AI$8=$CK$9,$CK31,IF(AI$8=$CL$9,$CL31,IF(AI$8=$CM$9,$CM31,IF(AI$8=$CN$9,$CN31,IF(AI$8=$CO$9,$CO31,IF(AI$8=$CP$9,$CP31,IF(AI$8=$CQ$9,$CQ31,"НЕТ")))))))))))))))))))))))) -> НЕТ | AJ31: =IF(AJ$8=$BT$9,$BT31,IF(AJ$8=$BS$9,$BS31,IF(AJ$8=$BU$9,$BU31,IF(AJ$8=$BV$9,$BV31,IF(AJ$8=$BW$9,$BW31,IF(AJ$8=$BX$9,$BX31,IF(AJ$8=$BY$9,$BY31,IF(AJ$8=$BZ$9,$BZ31,IF(AJ$8=$CA$9,$CA31,IF(AJ$8=$CC$9,$CC31,IF(AJ$8=$CD$9,$CD31,IF(AJ$8=$CE$9,$CE31,IF(AJ$8=$CF$9,$CF31,IF(AJ$8=$CG$9,$CG31,IF(AJ$8=$CH$9,$CH31,IF(AJ$8=$CI$9,$CI31,IF(AJ$8=$CJ$9,$CJ31,IF(AJ$8=$CK$9,$CK31,IF(AJ$8=$CL$9,$CL31,IF(AJ$8=$CM$9,$CM31,IF(AJ$8=$CN$9,$CN31,IF(AJ$8=$CO$9,$CO31,IF(AJ$8=$CP$9,$CP31,IF(AJ$8=$CQ$9,$CQ31,"НЕТ")))))))))))))))))))))))) -> НЕТ | AK31: =IF(AK$8=$BT$9,$BT31,IF(AK$8=$BS$9,$BS31,IF(AK$8=$BU$9,$BU31,IF(AK$8=$BV$9,$BV31,IF(AK$8=$BW$9,$BW31,IF(AK$8=$BX$9,$BX31,IF(AK$8=$BY$9,$BY31,IF(AK$8=$BZ$9,$BZ31,IF(AK$8=$CA$9,$CA31,IF(AK$8=$CC$9,$CC31,IF(AK$8=$CD$9,$CD31,IF(AK$8=$CE$9,$CE31,IF(AK$8=$CF$9,$CF31,IF(AK$8=$CG$9,$CG31,IF(AK$8=$CH$9,$CH31,IF(AK$8=$CI$9,$CI31,IF(AK$8=$CJ$9,$CJ31,IF(AK$8=$CK$9,$CK31,IF(AK$8=$CL$9,$CL31,IF(AK$8=$CM$9,$CM31,IF(AK$8=$CN$9,$CN31,IF(AK$8=$CO$9,$CO31,IF(AK$8=$CP$9,$CP31,IF(AK$8=$CQ$9,$CQ31,"НЕТ")))))))))))))))))))))))) -> НЕТ | AL31: =IF(AL$8=$BT$9,$BT31,IF(AL$8=$BS$9,$BS31,IF(AL$8=$BU$9,$BU31,IF(AL$8=$BV$9,$BV31,IF(AL$8=$BW$9,$BW31,IF(AL$8=$BX$9,$BX31,IF(AL$8=$BY$9,$BY31,IF(AL$8=$BZ$9,$BZ31,IF(AL$8=$CA$9,$CA31,IF(AL$8=$CC$9,$CC31,IF(AL$8=$CD$9,$CD31,IF(AL$8=$CE$9,$CE31,IF(AL$8=$CF$9,$CF31,IF(AL$8=$CG$9,$CG31,IF(AL$8=$CH$9,$CH31,IF(AL$8=$CI$9,$CI31,IF(AL$8=$CJ$9,$CJ31,IF(AL$8=$CK$9,$CK31,IF(AL$8=$CL$9,$CL31,IF(AL$8=$CM$9,$CM31,IF(AL$8=$CN$9,$CN31,IF(AL$8=$CO$9,$CO31,IF(AL$8=$CP$9,$CP31,IF(AL$8=$CQ$9,$CQ31,"НЕТ")))))))))))))))))))))))) -> НЕТ | AM31: =IF(AL31="НЕТ","Не требуется",$CR31) -> Не требуется | AS31: =IF(BS31="ДА",$M31,"") -> 1 | AT31: =IF(BT31="ДА",$M31,"") | AU31: =IF(BU31="ДА",$M31,"") | AV31: =IF(BV31="ДА",$M31,"") | AW31: =IF(BX31="ДА",$M31,"") -> 1 | AX31: =IF(BY31="ДА",$M31,"") -> 1 | AY31: =IF(BZ31="ДА",$M31,"") -> 1 | AZ31: =IF(CA31="ДА",$M31,"") -> 1 | BB31: =IF(CC31="ДА",$M31,"") -> 1 | BC31: =IF(CD31="ДА",$M31,"") -> 1 | BD31: =IF(CE31="ДА",$M31,"") | BE31: =IF(CF31="ДА",$M31,"") | BF31: =IF(CG31="ДА",$M31,"") | BG31: =IF(CH31="ДА",$M31,"") -> 1 | BH31: =IF(CI31="ДА",$M31,"") -> 1 | BI31: =IF(CJ31="ДА",$M31,"") | ... BP31: =IF(CQ31="ДА",$M31,"") | BS31: ДА | BT31: НЕТ | BU31: НЕТ | BV31: НЕТ | BW31: ДА | BX31: ДА | BY31: ДА | BZ31: ДА | CA31: ДА | CC31: ДА | CD31: ДА | CE31: НЕТ | CF31: НЕТ | CG31: НЕТ | CH31: ДА | CI31: ДА | CJ31: НЕТ | CK31: ДА | CL31: ДА | CM31: НЕТ | CN31: НЕТ | CO31: НЕТ | CP31: НЕТ | CQ31: НЕТ | CR31: Предоставляется Заказчиком
B32: Контроль исполнения проектов портфеля по методике ворот качества | C32: Признак "Ворота качества" у вехи имеется, фаз на данный момент нет | N32: =SUM(O32,R32,U32,X32) -> 0
