Workbook

Sheet МоделиУпр
C2: Тип производства/Виды деятельности
C3: Трудоемкое | R3: Трудоемкое+сборка | AB3: Материалоемкое | AC3: Фондо/ Финансовоемкое
B4: Сегменты | C4: НИПИ | H4: ИТ/консалтинг | M4: Проектный офис (Коммуникации и трекинг) | R4: Инжиниринг | W4: Медиа | AB4: Машиностроение/ проектное производство | AC4: Проектные инвестиции | AD4: Капстрой | AE4: Девелопмент
B5: Соло | C5: Ведение проекта для РП. | R5: Ведение проекта для РП (М) | AB5: Х | AC5: Х | AD5: Х | AG5: Шаги проработки
C6: =CONCATENATE("РП ",Соло!C3,"%") -> РП 27% | R6: =CONCATENATE("РП ",'Соло-М'!C3,"%") -> РП 19% | AH6: 1
B7: МикроГД | C7: Проектное управление для компании. Специалисты подчиняются ГД. | R7: Проектное управление для компании. Специалисты подчиняются ГД. (М) | AB7: Х | AC7: Х | AD7: Х | AH7: 2
C8: =CONCATENATE("ГД ",МикроГД!C3,"%") -> ГД 43% | E8: =CONCATENATE("РП ",МикроРП!C3,"%") -> РП 30% | H8: =CONCATENATE("ГД ",МикроГД!C3,"%") -> ГД 43% | J8: =CONCATENATE("РП ",МикроРП!C3,"%") -> РП 30% | M8: =CONCATENATE("ГД ",МикроГД!C3,"%") -> ГД 43% | O8: =CONCATENATE("РП ",МикроРП!C3,"%") -> РП 30% | R8: =CONCATENATE("ГД ",'МикроГД-М'!C3,"%") -> ГД 38% | T8: =CONCATENATE("РП ",'МикроРП-М'!C3,"%") -> РП 37% | W8: =CONCATENATE("ГД ",'МикроГД-М'!C3,"%") -> ГД 38% | Y8: =CONCATENATE("РП ",'МикроРП-М'!C3,"%") -> РП 37% | AH8: 3
B9: МикроРСП | C9: Проектное управление для подразделения. Специалисты подчиняются РСП. | R9: Проектное управление для подразделения. Специалисты подчиняются РСП. (М) | AB9: Х | AC9: Х | AD9: Х | AH9: 4
C10: =CONCATENATE("РСП ",МикроРСП!C3,"%") -> РСП 32% | E10: =CONCATENATE("РП ",МикроРП!C3,"%") -> РП 30% | H10: =CONCATENATE("РСП ",МикроРСП!C3,"%") -> РСП 32% | J10: =CONCATENATE("РП ",МикроРП!C3,"%") -> РП 30% | M10: =CONCATENATE("РСП ",МикроРСП!C3,"%") -> РСП 32% | O10: =CONCATENATE("РП ",МикроРП!C3,"%") -> РП 30% | R10: =CONCATENATE("РСП ",'МикроРСП-М'!C3,"%") -> РСП 35% | T10: =CONCATENATE("РП ",'МикроРП-М'!C3,"%") -> РП 37% | W10: =CONCATENATE("РСП ",'МикроРСП-М'!C3,"%") -> РСП 35% | Y10: =CONCATENATE("РП ",'МикроРП-М'!C3,"%") -> РП 37% | AH10: 5
B11: Малый1 | C11: Нескольких проектных направлений. Проекты в рамках направлений. | R11: Нескольких проектных направлений. Проекты в рамках направлений. (М) | AB11: Х | AC11: Х | AD11: Х
C12: =CONCATENATE("ГД ",'Мал1-2ГД'!C3,"%") -> ГД 46% | D12: =CONCATENATE("ФД ",'Мал1-2ФД'!C3,"%") -> ФД 58% | E12: =CONCATENATE("РП ",'Мал1-2РП'!C3,"%") -> РП 30% | G12: =CONCATENATE("РН ",Мал1РН!C3,"%") -> РН 37% | H12: =CONCATENATE("ГД ",'Мал1-2ГД'!C3,"%") -> ГД 46% | I12: =CONCATENATE("ФД ",'Мал1-2ФД'!C3,"%") -> ФД 58% | K12: =CONCATENATE("РП ",'Мал1-2РП'!C3,"%") -> РП 30% | L12: =CONCATENATE("РН ",Мал1РН!C3,"%") -> РН 37% | M12: =CONCATENATE("ГД ",'Мал1-2ГД'!C3,"%") -> ГД 46% | N12: =CONCATENATE("ФД ",'Мал1-2ФД'!C3,"%") -> ФД 58% | O12: =CONCATENATE("РП ",'Мал1-2РП'!C3,"%") -> РП 30% | Q12: =CONCATENATE("РН ",Мал1РН!C3,"%") -> РН 37% | R12: =CONCATENATE("ГД ",'Мал1-2ГД'!C3,"%") -> ГД 46% | S12: =CONCATENATE("ФД ",'Мал1-2ФД'!C3,"%") -> ФД 58% | T12: =CONCATENATE("РП ",'Мал1-2РП-М'!C3,"%") -> РП 37% | V12: =CONCATENATE("РН ",'Мал1РН-М'!C3,"%") -> РН 36% | W12: =CONCATENATE("ГД ",'Мал1-2ГД'!C3,"%") -> ГД 46% | X12: =CONCATENATE("ФД ",'Мал1-2ФД'!C3,"%") -> ФД 58% | Z12: =CONCATENATE("РП ",'Мал1-2РП-М'!C3,"%") -> РП 37% | AA12: =CONCATENATE("РН ",'Мал1РН-М'!C3,"%") -> РН 36%
B13: Малый2.1. | C13: Проектное управление для организации со слабоматричной структурой. Сквозные проекты. | R13: Слабоматричная структура. Сквозные проекты. (М) | AB13: Х | AC13: Х | AD13: Х
C14: =CONCATENATE("ГД ",'Мал1-2ГД'!C3,"%") -> ГД 46% | D14: =CONCATENATE("ФД ",'Мал1-2ФД'!C3,"%") -> ФД 58% | E14: =CONCATENATE("РП ",'Мал1-2РП'!C3,"%") -> РП 30% | G14: =CONCATENATE("ППО ",Мал2ППО!C3,"%") -> ППО 30% | H14: =CONCATENATE("ГД ",'Мал1-2ГД'!C3,"%") -> ГД 46% | I14: =CONCATENATE("ФД ",'Мал1-2ФД'!C3,"%") -> ФД 58% | K14: =CONCATENATE("РП ",'Мал1-2РП'!C3,"%") -> РП 30% | L14: =CONCATENATE("ППО ",Мал2ППО!C3,"%") -> ППО 30% | M14: =CONCATENATE("ГД ",'Мал1-2ГД'!C3,"%") -> ГД 46% | N14: =CONCATENATE("ФД ",'Мал1-2ФД'!C3,"%") -> ФД 58% | O14: =CONCATENATE("РП ",'Мал1-2РП'!C3,"%") -> РП 30% | Q14: =CONCATENATE("ППО ",Мал2ППО!C3,"%") -> ППО 30% | R14: =CONCATENATE("ГД ",'Мал1-2ГД'!C3,"%") -> ГД 46% | S14: =CONCATENATE("ФД ",'Мал1-2ФД'!C3,"%") -> ФД 58% | T14: =CONCATENATE("РП ",'Мал1-2РП-М'!C3,"%") -> РП 37% | V14: =CONCATENATE("ППО ",'Мал2ППО-М'!C3,"%") -> ППО 30% | W14: =CONCATENATE("ГД ",'Мал1-2ГД'!C3,"%") -> ГД 46% | X14: =CONCATENATE("ФД ",'Мал1-2ФД'!C3,"%") -> ФД 58% | Z14: =CONCATENATE("РП ",'Мал1-2РП-М'!C3,"%") -> РП 37% | AA14: =CONCATENATE("ППО ",'Мал2ППО-М'!C3,"%") -> ППО 30%
B15: Малый2.2. | C15: Проектное управление для организации с сильноматричной структурой. Сквозные проекты. | R15: Сильноматрична структура. Сквозные проекты.(М) | AB15: Х | AC15: Х | AD15: Х
C16: =CONCATENATE("ГД ",'Мал1-2ГД'!C3,"%") -> ГД 46% | D16: =CONCATENATE("ФД ",'Мал1-2ФД'!C3,"%") -> ФД 58% | E16: =CONCATENATE("РП ",'Мал1-2РП'!C3,"%") -> РП 30% | G16: =CONCATENATE("ППО ",Мал2ППО!C3,"%") -> ППО 30% | H16: =CONCATENATE("ГД ",'Мал1-2ГД'!C3,"%") -> ГД 46% | I16: =CONCATENATE("ФД ",'Мал1-2ФД'!C3,"%") -> ФД 58% | K16: =CONCATENATE("РП ",'Мал1-2РП'!C3,"%") -> РП 30% | L16: =CONCATENATE("ППО ",Мал2ППО!C3,"%") -> ППО 30% | M16: =CONCATENATE("ГД ",'Мал1-2ГД'!C3,"%") -> ГД 46% | N16: =CONCATENATE("ФД ",'Мал1-2ФД'!C3,"%") -> ФД 58% | O16: =CONCATENATE("РП ",'Мал1-2РП'!C3,"%") -> РП 30% | Q16: =CONCATENATE("ППО ",Мал2ППО!C3,"%") -> ППО 30% | R16: =CONCATENATE("ГД ",'Мал1-2ГД'!C3,"%") -> ГД 46% | S16: =CONCATENATE("ФД ",'Мал1-2ФД'!C3,"%") -> ФД 58% | T16: =CONCATENATE("РП ",'Мал1-2РП-М'!C3,"%") -> РП 37% | V16: =CONCATENATE("ППО ",'Мал2ППО-М'!C3,"%") -> ППО 30% | W16: =CONCATENATE("ГД ",'Мал1-2ГД'!C3,"%") -> ГД 46% | X16: =CONCATENATE("ФД ",'Мал1-2ФД'!C3,"%") -> ФД 58% | Z16: =CONCATENATE("РП ",'Мал1-2РП-М'!C3,"%") -> РП 37% | AA16: =CONCATENATE("ППО ",'Мал2ППО-М'!C3,"%") -> ППО 30%
B17: Средний1 | C17: Средний1.ПЭО+ПДО. Заказчик - ФД | H17: Х | M17: Х | R17: Х | W17: Х
C18: =CONCATENATE("ФД ",Ср1ФД!C3,"%") -> ФД 55% | E18: =CONCATENATE("ПДО ",Ср1ПДО!C3,"%") -> ПДО 38%
B19: Средний2 | C19: Средний2.НИПИ без РП. Дир. по произв-ву и ФД | H19: Х | M19: Х | R19: Средний2.НИПИ без РП. Дир. по произв-ву и ФД (М)
C20: =CONCATENATE("ГД ",'Ср2-5ГД'!C3,"%") -> ГД 50% | D20: =CONCATENATE("ДП ",Ср2ДП!C3,"%") -> ДП 33% | E20: =CONCATENATE("ППО ",Ср2ППО!C3,"%") -> ППО 38% | G20: =CONCATENATE("ФД ",'Ср2-5ФД'!C3,"%") -> ФД 55% | R20: =CONCATENATE("ГД ",'Ср2-5ГД'!C3,"%") -> ГД 50% | S20: =CONCATENATE("ДП ",'Ср2ДП-М'!C3,"%") -> ДП 21% | T20: =CONCATENATE("ППО ",Ср2ППО!C3,"%") -> ППО 38% | V20: =CONCATENATE("ФД ",'Ср2-5ФД'!C3,"%") -> ФД 55% | W20: =CONCATENATE("ГД ",'Ср2-5ГД'!C3,"%") -> ГД 50% | X20: =CONCATENATE("ДП ",'Ср2ДП-М'!C3,"%") -> ДП 21% | Y20: =CONCATENATE("ППО ",Ср2ППО!C3,"%") -> ППО 38% | AA20: =CONCATENATE("ФД ",'Ср2-5ФД'!C3,"%") -> ФД 55%
B21: Средний3-5 | C21: Средний3.НИПИ | H21: Средний5.ИТ. Буккирование. Контрактация. Произв. отделы участвуют в управлении. | R21: Средний4.Инжиниринг
C22: =CONCATENATE("ГД ",'Ср2-5ГД'!C3,"%") -> ГД 50% | D22: =CONCATENATE("ДП ",Ср3ДП!C3,"%") -> ДП 28% | E22: =CONCATENATE("ППО ", Ср3ППО!C3,"%") -> ППО 18% | F22: =CONCATENATE("РП ",Ср3РП!C3,"%") -> РП 28% | G22: =CONCATENATE("ФД ",'Ср2-5ФД'!C3,"%") -> ФД 55% | H22: =CONCATENATE("ГД ",'Ср2-5ГД'!C3,"%") -> ГД 50% | I22: =CONCATENATE("РПО ",Ср5РПО!C3,"%") -> РПО 29% | J22: =CONCATENATE("ПрОф ",Ср5ПрОф!C3,"%") -> ПрОф 24% | K22: =CONCATENATE("РП ",Ср5РП!C3,"%") -> РП 31% | L22: =CONCATENATE("ФД ",'Ср2-5ФД'!C3,"%") -> ФД 55% | M22: =CONCATENATE("ГД ",'Ср2-5ГД'!C3,"%") -> ГД 50% | N22: =CONCATENATE("РПО ",Ср5РПО!C3,"%") -> РПО 29% | O22: =CONCATENATE("ПрОф ",Ср5ПрОф!C3,"%") -> ПрОф 24% | P22: =CONCATENATE("РП ",Ср5РП!C3,"%") -> РП 31% | Q22: =CONCATENATE("ФД ",'Ср2-5ФД'!C3,"%") -> ФД 55% | R22: =CONCATENATE("ГД ",'Ср2-5ГД'!C3,"%") -> ГД 50% | S22: =CONCATENATE("ДПм ",'Ср4ДПм-М'!C3,"%") -> ДПм 22% | T22: =CONCATENATE("РПО ",'Ср4РПО-М'!C3,"%") -> РПО 20% | U22: =CONCATENATE("РП ",'Ср4РП-М'!C3,"%") -> РП 31% | V22: =CONCATENATE("ФД ",'Ср2-5ФД'!C3,"%") -> ФД 55% | W22: =CONCATENATE("ГД ",'Ср2-5ГД'!C3,"%") -> ГД 50% | X22: =CONCATENATE("ДПм ",'Ср4ДПм-М'!C3,"%") -> ДПм 22% | Y22: =CONCATENATE("РПО ",'Ср4РПО-М'!C3,"%") -> РПО 20% | Z22: =CONCATENATE("РП ",'Ср4РП-М'!C3,"%") -> РП 31% | AA22: =CONCATENATE("ФД ",'Ср2-5ФД'!C3,"%") -> ФД 55%
B23: Крупный1 | C23: Институт в Институте. Проекты в рамках направлений. | R23: Институт в Институте. Проекты в рамках направлений.
C24: =CONCATENATE("1ЗГД ",Кр11ЗГД!C3,"%") -> 1ЗГД 20% | D24: =CONCATENATE("ППО ",Кр1ППО!C3,"%") -> ППО 44% | E24: =CONCATENATE("РЦ ",Кр1РЦ!C3,"%") -> РЦ 18% | F24: =CONCATENATE("ПДО ",Кр1ПДО!C3,"%") -> ПДО 23% | G24: =CONCATENATE("РП ",Кр1РП!C3,"%") -> РП 31% | H24: =CONCATENATE("1ЗГД ",Кр11ЗГД!C3,"%") -> 1ЗГД 20% | I24: =CONCATENATE("ППО ",Кр1ППО!C3,"%") -> ППО 44% | J24: =CONCATENATE("РЦ ",Кр1РЦ!C3,"%") -> РЦ 18% | K24: =CONCATENATE("ПДО ",Кр1ПДО!C3,"%") -> ПДО 23% | L24: =CONCATENATE("РП ",Кр1РП!C3,"%") -> РП 31% | M24: =CONCATENATE("1ЗГД ",Кр11ЗГД!C3,"%") -> 1ЗГД 20% | N24: =CONCATENATE("ППО ",Кр1ППО!C3,"%") -> ППО 44% | O24: =CONCATENATE("РЦ ",Кр1РЦ!C3,"%") -> РЦ 18% | P24: =CONCATENATE("ПДО ",Кр1ПДО!C3,"%") -> ПДО 23% | Q24: =CONCATENATE("РП ",Кр1РП!C3,"%") -> РП 31% | R24: =CONCATENATE("1ЗГД ",Кр11ЗГД!C3,"%") -> 1ЗГД 20% | S24: =CONCATENATE("ППО ",'Кр1ППО-М'!C3,"%") -> ППО 47% | T24: =CONCATENATE("РЦ ",'Кр1РЦ-М'!C3,"%") -> РЦ 18% | U24: =CONCATENATE("ПДО ",'Кр1ПДО-М'!C3,"%") -> ПДО 23% | V24: =CONCATENATE("РП ",'Кр1РП-М'!C3,"%") -> РП 32% | W24: =CONCATENATE("1ЗГД ",Кр11ЗГД!C3,"%") -> 1ЗГД 20% | X24: =CONCATENATE("ППО ",'Кр1ППО-М'!C3,"%") -> ППО 47% | Y24: =CONCATENATE("РЦ ",'Кр1РЦ-М'!C3,"%") -> РЦ 18% | Z24: =CONCATENATE("ПДО ",'Кр1ПДО-М'!C3,"%") -> ПДО 23% | AA24: =CONCATENATE("РП ",'Кр1РП-М'!C3,"%") -> РП 32%
B25: Крупный2 | C25: Х | H25: Х | M25: Х | R25: Х | AB25: Сквозные проекты. Два уровня диспетчеров.
AB26: =CONCATENATE("ДП ",Кр2МшДПр!C3,"%") -> ДП 25%
B27: Холдинг1.1. | C27: ППО и ДЗО в одной базе | R27: ППО и ДЗО в одной базе
C28: =CONCATENATE("ППО ",Х1_ППО!C3,"%") -> ППО 33% | R28: =CONCATENATE("ППО ",'Х1_ППО-М'!C3,"%") -> ППО 40%
B29: Холдинг 1.2. | C29: ППО и ДЗО в разных базах | R29: ППО и ДЗО в разных базах
C30: =CONCATENATE("ППО ",Х1_ППО!C3,"%") -> ППО 33% | R30: =CONCATENATE("ППО ",'Х1_ППО-М'!C3,"%") -> ППО 40%
B31: Холдинг2 | C31: УК-ДЗО. Инвестиционные проекты. Gate, Заявки
C32: =CONCATENATE("ДИД ",Х2_ДИД!C3,"%") -> ДИД 25% | E32: =CONCATENATE("НИО ",Х2_НИО!C3,"%") -> НИО 8%

Sheet Решения
B1: Идея | C1: Статус | E1: Комментарий
B2: 1С:Взаимодействие | C2: 0 | D2: 1 | E2: Нет в сценарии
B3: Gate | C3: 0.5 | G3: 1
B4: MDR | C4: 0 | D4: 1
B5: Актуализация и балансировка фин.планов | C5: 0.5 | D5: 1
B6: Актуализация инвестпрограммы на основании связанных проектов | C6: 0.5
B7: Актуализация информации по проектам | C7: 0.5 | D7: 1
B8: Анализ обеспеченности (в т.ч. ТМЦ) и формирование фронта работ | C8: 0
B9: Анализ обеспеченности и формирование фронта работ | C9: 0
B10: Балансировка и минимизация кассовых разрывов | C10: 0.5 | D10: 1
B11: Балансировка объемов и минимизация ресурсных конфликтов | C11: 0.5
B12: Бронирование базовое | C12: 0
B13: Бюджеты для финансирования возможностей | C13: 0.5
B14: Влияние производительности ресурсов на трудоемкость и сроки | C14: 0.5
B15: Диспетчирование работ (поручения) | C15: 0.5 | D15: 1
B16: Единообразное планирование проектов (План-график, трудозатраты, фин план) | C16: 0.5 | D16: 1
B17: Загрузка из файла-шаблона с PDM/PLM данными. Состав изделия, состав работ, связи | C17: 0
B18: Инвестзаявки в системе | C18: 0.5 | G18: 1
B19: Инвестпрограмма | C19: 0.5 | G19: 1
B20: Интеграция баз Холдинг-ДЗО | C20: 0
B21: Интеграция с КИС | C21: 0
B22: Интеграция с системой управления проектами | C22: 0
B23: Интеграция с трекинг-системами | C23: 0.5 | D23: 1
B24: Канбан-доска | C24: 0 | D24: 1 | E24: Нет Функций ИС
B25: Контроль актирования | C25: 0
B26: Контроль качества и применимость ресурсов (компетенции, квалификации) | C26: 0
B27: Механизм укрупненной оценки проектов на структуре проекта с печатной формой (Обоснование стоимости проекта) | C27: 0.3 | D27: 1 | G27: 1
B28: Многомерные проекты | C28: 0.5 | D28: 1 | E28: Нет Функций ИС
B29: Объединенные закупки (лоты) | C29: 0
B30: Оперативный фронт работ (план производственных подраз): - подошли сроки, работы обеспечены, баласировки под мощность подразделений | C30: 0
B31: Отметка в работах проекта о наличии ТМЦ из спецификаций и смена статуса работ на "обеспеченные" | C31: 0
B32: Платежный календарь | C32: 0.5 | D32: 1
B33: Подробные планы загрузки сотрудников | C33: 0.5 | D33: 1
B34: Привязка спецификаций к работам проекта | C34: 0
B35: Проектный документооборот (~MDR базовый) (жизненный цикл основных проектных артефактов, указанных в ТЗ и договоре) | C35: 0 | D35: 1
B36: Проектный калькулятор | C36: 0.5
B37: Расчет финпоказателей в заявках | C37: 0.5 | G37: 1
B38: РСП: управление пакетами работ, за которые они назначены ответственными | C38: 0 | G38: 1
B39: Сводная картина по экономике фирмы и ден.потоку на основании актуального сводного плана и плана инвестиций | C39: 0.5
B40: Связь проектов, заказов поставщикам и факта поставки ТМЦ | C40: 0.8
...

Sheet НИПИ_списком
B2: Оглавление Lean Canvas Model для РМ5
B4: Сегмент | C4: LCM | D4: Вид заказчика. Краткое описание | E4: Специфическая задача сегмента | F4: Особенности | G4: Вид продукта PM | H4: Вид комплексного продукта PM | I4: ДО | J4: Корп.бюдж. (+Казна) | K4: Учет
B5: Соло | C5: РП | D5: Заказчик - РП под свои проекты. | E5: Ведение проекта для РП | F5: Простой аналог работы в MS Project и MS Excel. Каждый РП ведет свой проект. Бюджетирование проектов. Многомерные проекты, Проектная продукция, task tracker+канбан-доска с лимитами | G5: PM.ПРОФ в ГРМ/ | H5: - | I5: Диск | J5: - | K5: -
D6: Есть исполнители. | G6: PM.Стандарт
B7: МикроГД | C7: ГД | D7: До 60 человек; Заказчик – ГД. В управлении нет руководителей производственных отделов | E7: Проектное управление | F7: Управление ресурсами | G7: PM.ПРОФ | H7: УНФ+PM | I7: ДО | J7: УНФ/Свое | K7: УНФ/БП
B8: МикроРСП | C8: РСП | D8: Заказчик – руководитель подразделения внутри организации | E8: для организации с функц. или проектной структурами | F8: (доступность, решение конфликтов), Моделирование проектной загрузки. Бюджетирование по организации. Косвенные по организации в целом. Структура проектов предприятия (EPS) | G8: PM.ПРОФ | H8: УНФ+PM | I8: ДО | J8: УНФ/Свое | K8: УНФ/ERP/БП
B9: Малый1 | C9: ГД | D9: 60-200 человек; Направления со своим управлением. | E9: Разрез по подразделениям в произв. и экономических данных | F9: Темплан. Объемное планирование, ресурсные планы. Бюджетирование по подразделениям. Финрез по подразделениям и косвенные затраты по подразделениям | G9: PM.ПРОФ | H9: УНФ+PM ERP+PM | I9: ДО/Другие | J9: УНФ/ERP/Свое | K9: УНФ/ERP/БП
C10: ФД | D10: Проекты внутри направлений.
C11: РукНапр | D11: Разрез по подразделениям в произв. и экономических данных
B12: Малый2 | C12: ГД | D12: 60-200 человек; ГИПы+Рук.подр., сквозные проекты, | E12: Проектное управление для организации с матричной стр. | F12: Поддержка матричной системы, бронирование | G12: PM.КОРП | H12: УНФ+PM ERP+PM | I12: ДО/Другие | J12: УНФ/ERP/Свое | K12: УНФ/ERP/БП
C13: ФД
C14: РПО | D14: Производственные отделы участвуют в управлении
B15: Средний1 | C15: ФД | D15: 200-600 человек; | E15: Проектное управление | F15: Контрактация проектов. | G15: PM.КОРП | H15: ERP+PM | I15: ДО/Другие | J15: ERP/Свое | K15: ERP/БП
D16: ПЭО и ПДО под ФД | E16: для организации с матричной структурой | F16: Проектный калькулятор.
B17: Средний2 | C17: ГД | D17: 200-600 человек; | E17: +Оценка и Контрактация | F17: Управление договорами. | G17: PM.КОРП | H17: ERP+PM | I17: ДО/Другие | J17: ERP/Свое | K17: ERP/БП
C18: ДП
C19: ФД | D19: Дир.Произв и ФД | F19: Модели управления портфелями, программами. Фазы.
B20: Средний3 | C20: ГД | D20: 200-600 человек; НИПИ, ГИПы+Рук.подр. | F20: Ведение графиков проектов в несколько десятков тысяч строк. | G20: PM.КОРП | H20: ERP+PM | I20: ДО/Другие | J20: ERP/Свое | K20: ERP/БП
C21: ДП | D21: Производственные отделы участвуют в управлении; | F21: ГОЗ (Специальные счета казначейства, контроль БДДС по счетам, учет трудозатрат в разрезе работ по ГОЗ), Иерархические проекты.
C22: ФД | D22: м.б. Контрактация | F22: MDR – управление реестром и структурой документации. Управление рисками.
B23: Средний4 | C23: ГД | D23: 200-600 человек; Инж, ГИПы+Рук.подр. | F23: Моделирование «что если» внутри проекта. | G23: PM.КОРП | H23: ERP+PM | I23: ДО/Другие | J23: ERP/Свое | K23: ERP/БП
C24: ДП | D24: Производственные отделы участвуют в управлении; | F24: Мат.нормирование проекта (по драйверам).
C25: ФД | D25: м.б. Контрактация | F25: API c системами управления проектами и объемами.
B26: Средний5 ИТ | C26: ГД | D26: 200-600 человек; ИТ | G26: PM.КОРП | H26: ERP+PM | I26: ДО/Другие | J26: ERP/Свое | K26: ERP/БП
C27: ДП | D27: Производственные отделы участвуют в управлении;
C28: ФД | D28: Контрактация, буккирование.
B29: Крупный1 | C29: 1-й зам ГД/ИспДир | D29: 600-3000 человек; | E29: Проектное управление для организации со сложной иерархической структурой | F29: Институт в институте. | G29: PM.КОРП | H29: ? | I29: ДО/Другие | J29: ERP/УХ/Свое | K29: УХ + ERP/УХ/БП
C30: РукЦентров | D30: Институт в институте; 2 уровня ПЭО | G30: (? PM.КОРП Холдинг)
B31: Крупный2 | C31: ДП | D31: 600-3000 человек; | G31: PM.КОРП | H31: ? | I31: ДО/Другие | J31: УХ | K31: УХ + Шаблон на ERP
D32: Сквозные проекты; 2 уровня диспетчеров | G32: (? PM.КОРП Холдинг) | J32: (УХ.ERP в ДЗО)
B33: Холдинг1.1/ Кооперация | C33: ППО | D33: Головной-Соисполнители. Сквозные проекты. Головной ППО и ДЗО в одной базе | E33: Управление работами соисполнителей | F33: Общее управление ресурсами (Голова-Соисп.) | G33: PM.КОРП Упр.Кооп.(?) | H33: ? | I33: ДО/Другие | J33: - | K33: -
B34: Холдинг1.2/ Кооперация | C34: ППО | D34: Головной-Соисполнители. Сквозные проекты. Головной ППО и ДЗО в разных базах | E34: Управление работами соисполнителей | F34: Общее управление ресурсами (Голова-Соисп.) Иерархические проекты в разных базах. | G34: PM.КОРП Упр.Кооп.(?) | H34: ? | I34: ДО/Другие | J34: - | K34: -
B35: Холдинг2 Инвест | C35: ДИД | D35: Холдинг. УК-ДЗО. | E35: Управление инвестпрограммой | F35: Заявки, Gate, Моделирование «что если» для инвестпрограммы. | G35: PM.КОРП Холдинг | H35: ? | I35: ДО/Другие | J35: УХ (УХ.ERP в ДЗО) | K35: УХ + Шаблон на ERP
C36: НИО | D36: Инвестиционные проекты. Gate, Заявки
B38: Концепция | C38: e1cib/data/Справочник.Файлы?ref=80f7000c295e34e311ea467fc0ee57af

Sheet Проекты и бюджеты под контролем
B2: Продукт | I2: Рынок
B3: 2.1 Проблема | C3: 2.1. Сопоставление с проблемами в презентации | D3: =ROUND(AVERAGE(D6:D16),2) -> 0.5 | E3: 4. Решение | F3: Связь | G3: =AVERAGE(G4:G16) -> 0.61111111 | H3: 3. Уникальная ценность (УТП) | J3: 9. Скрытое преимущество | K3: 1.1 Сегменты потребителей
B4: 1.1. Остутствие единой среды ведения проектов - все ведут проекты в разных инструментах | C4: НА старте портфеля разрозненные инструменты работают, но по мере роста кол-ва проектов, появляются органичения. Существующая система перестала работать? (общая канва, не отдельная проблематика в презентации) | D4: =ROUND(AVERAGE(D8:D13),2) -> 0.39 | E4: Единое окно с набором актуальных показателей по реестру проектов (БДР, риски, сроки). Панель руководителя | F4: 1.1. | G4: 0.8 | H4: 1С:PM Создает единую управленческую среду где данные обновляются в процессе работы, а руководитель видит отклонение, ответсвенных и последствия в одном контуре: - Елиные правила управления (ПРоекты ведутся в общей логике: структура, роли и контрольные точки) - Контроль через отклонения (Руководитель видит где проблема и может сразу провалиться в причину) - Связь проектов и экономики (Сроки, жтапы и фин. показатели связаны между собой. Изменения сразу отражаются на бюджете) Порядок в проектах при любом текущем состоянии проектного управления Уверенная основа для дальнейшего развития проектного управления За счет айтисистемы и методической оддержки вы получите: Дашборд с консолидированной информацией о состоянии проектов (вехи, сроки, бюджеты, риски) Минимизация трудозатрат руководителя на получение информации о состоянии проектов Быстрый и легкий старт работы в системе Автомический контроль исполнительской дисциплины Стоимость до 2,5 млн., сроки - до 2х мес. запуска | J4: Богатый базовый фунционал решения Возможность повторения уникальной отчетности Возможность Интеграции с учетными системами: БУХ, УНФ, ERP | K4: Для компаний с начальным уровнем проектного управления (внешние проекты - оборот 800М до 4Я), (внутренние проекты - оборот от 2Я). Генеральный директор / РПО / ТОП Менеджер (ответсвенный за проектную деятельность) - потребитель отчетности от РП. осуществляет контроль за ходом реализации реестра проектов в одном окне (Вехи), показатели (план/факт сроки, бюджеты, риски). В основном контроль за внутренними проектами. РП (администратор проекта) - быстрое ведение проектов без детализации до объемов и ресурсов актуализация План/факт Вехи, сроки, бюджет, риски Тригеры: 1. Существующая система перестала работать из-за использования разрозненных инструментов, и отсетствия методики ведения проектов 2. Управленческие решения запаздывают из-за отсутсвия актуальной информации по проектам
B5: 1. Большое кол-во разрозненной информации по проектам, не понятно, на что уделить внимание - ключевые показатели всегда перед глазами онлайн | C5: Проблема: Нет фокуса. Руководителю сложно понять какие проекты требуют внимания,
B6: 1.1. Остутствие единой среды ведения проектов - все ведут проекты по разному | C6: Проблема: Проекты ведутся по разным правилам и с разной детализацией. | D6: =AVERAGE(G4,G7) -> 0.8 | E6: Совокупность Вех по всем проектам (аналог ВК в панели руководителя)
B7: 1.2. Остутсвие актуальной информации по проектам (на какой вехе/ кто за нее ответсвенный | C7: Проблематика: .2.Размытая ответственность за проекты и их задачи. Добавить раздел в презентацию. | E7: Отвественные за проекты (РП), ответсвенные за задачи | F7: 1.1. | G7: 0.8
B8: 1.2. Остутсвие актуальной информации по проектам (, попадаем ли в сроки, есть/нет ли рисков, подписаны ли акты, списание ДС. ) - тратим много времени на сбор акутальной информации | C8: 1. Проблема: Экономика и сроки ведутся в разных инструментах. 2. Проблема: Отчетность собирается вручную и быстро устаревает | D8: =AVERAGE(G10,G9,G11,G12,G13) -> 0.68
B9: 1.3. РП Забывают внести данные - смотрим на ситуацию в прошлом | C9: Проблема: РП Забывают внести данные (Добавить новый раздел) | D9: =AVERAGE(G14) -> 0 | E9: КСГ проекта / актируемые этапы - план/факт сроков | F9: 1.2. | G9: 0.8
B10: 2. Оперативный и достоверный учет фактических данных по первичным документам - опция 1 | C10: Проблема: Факт по бюджетам ведется в учетной системе и не сопоставим с планом. Нужно видеть факт в проектах вплоть до первичных документов. Двойной ввод данных | E10: Контрольных точек ( Проектные решения - ответственных за них) план/факт исполнения КТ; Вехам (из-за чего проиходит сдвиг, какие промблемы) | F10: 1.2. | G10: 0.5
B11: 3. Актуальный БДР и БДДС по портфелю (план и факт) - опция 2 | C11: Не получить актуальный прогноз по бюджетам портфеля с учетом фактических данных Трудоемко обновлять план с учетом фактических отклонений.. | E11: Потенциальные риски Есть/нет наличие | F11: 1.2. | G11: 0.5
E12: БДР и БДДС - План/факт | F12: 1.2. | G12: 0.8
B13: 1.4. Порядок | C13: Проблема: Система сама по себе не наводит порядок без правил. | D13: =AVERAGE(G15) -> 0.5 | E13: Факт и актуализация в ручном режиме | F13: 1.2. | G13: 0.8
E14: Автоматический контроль за актуализацией данных | F14: 1.3. | G14: 0
E15: Методическая поддержка | F15: 1.4. | G15: 0.5
B17: 2.2 Альтернативы | E17: 8. Ключевые метрики | J17: 5. Каналы | K17: 1.2 Ранние последователи
B18: Битрикс 24 Excel Он-лайн табличный процессор Адванта (базовый запуск) Яндекс трекер Импортозамещается: Шарепоинт + ПроджектСервер + Локальный Проджект + MS BI | E18: Количество продаж; Количество пользователей в ГРМ; Количество отзывов | K18: Х продаж за первые 3 мес.; У продаж за вторые 3 мес.
B19: 7. Структура издержек | I19: 6. Потоки прибыли
B22: решение не сформулировано | E22: Не занимались | F22: 0 | H22: Что нужно доработать:
B23: решение сформулировано частично | E23: В работе | F23: 0.1
B24: решение сформулировано | E24: Техническая реализация | F24: 0.5
E25: Базовая реализация (в т.ч. удобно) | F25: 0.8
E26: Глубокая реализация | F26: 1 | H26: Что нужно ОП для старта: демо-база, презентации.
B31: РАС Промблематика: | E31: Для кого: Генеральный директор (РПО)
B32: 1. Большое кол-во разразненной информации по проектам, не понятно на что уделить внимание - ключевые показатели всегда перед глазами онлайн | E32: Исполнитель - РП
B33: 1.1. Остутствие едиой среды ведения проектов - все ведут проекты по разному в разных инструментах
B34: 1.2. Остутсвие актуальной информации по проектам (на какой вехи/ кто за нее ответсвенный, попадаем ли в сроки, есть/нет ли рисков, подписаны ли акты, списание ДС. ) - тратим много времени на сбор акутальной информации | E34: Бизнес задача: Верхнеуровневый контроль состояния проектов реестра
B35: 1.3. РП Забывают внести данные - смотрим на ситуацию в прошлом
E36: Актуальная информация по реестру проектов в разрезе (анализ текущего состоянию проектов):
E37: КСГ проекта (актируемые этапы) план/факт сроков
E38: Контрольных точек ( Проектные решения - ответственных за них) план/факт исполнения КТ
E39: Потенциальные риски Есть/нет наличие
E40: БДР и БДДС - План/факт
E42: Факт и актуализация в ручном режиме
B46: сколько запросов под эту тематику за год было
B47: больше 2 млдр. Не Трудоемкое производство - 90 SQL
B48: как первый шаг на РМ5 для стандарт проектов - 119 SQL
B49: запросов какое количество было бы куплено
B50: больше 2 млдр. Не Трудоемкое производство - 19
B51: как первый шаг на РМ5 для стандарт проектов - 41
B52: какое количество заказчиков купило бы такое предложение из текущей воронки
...

Sheet ПиБпК_после вебинара
B2: Продукт | H2: Рынок
B3: 2.1 Проблема | D3: 4. Решение | E3: Связь | F3: =AVERAGE(F4:F16) -> 0.61111111 | G3: 3. Уникальная ценность (УТП) | I3: 9. Скрытое преимущество | J3: 1.1 Сегменты потребителей
B4: Нет фокуса. Руководителю сложно понять, какие проекты требуют внимания | D4: Единая панель по портфелю проектов с индикаторами состояния проекта по срокам, бюджету и наличия рисков | F4: 0.8 | G4: Единое окно с набором актуальных показателей по проекту и ответственным Единые правила управления. Проекты ведутся в общей логике: структура, роли, контрольные точки Финансы в привязке к срокам проектов. Сроки, этапы и бюджеты связаны между собой, изменения сразу отражаются в отчетности Контрольные точки. Контроль графика ведения проектов по вехам и ответственным Данные «до первички» Возможность «провалиться» в проект и узнать всю информацию о проекте до первички Стоимость до 2,5 млн., сроки - до 2х мес. запуска | I4: Богатый базовый фунционал решения Возможность повторения уникальной отчетности Возможность Интеграции с учетными системами: БУХ, УНФ, ERP | J4: Для компаний с начальным уровнем проектного управления (внешние проекты - оборот 800М до 4Я), (внутренние проекты - оборот от 2Я). Генеральный директор / РПО / ТОП Менеджер (ответсвенный за проектную деятельность) - потребитель отчетности от РП. осуществляет контроль за ходом реализации реестра проектов в одном окне (Вехи), показатели (план/факт сроки, бюджеты, риски). В основном контроль за внутренними проектами. РП (администратор проекта) - быстрое ведение проектов без детализации до объемов и ресурсов актуализация План/факт Вехи, сроки, бюджет, риски Тригеры: 1. Существующая система перестала работать из-за использования разрозненных инструментов, и отсетствия методики ведения проектов 2. Управленческие решения запаздывают из-за отсутсвия актуальной информации по проектам
B5: Размытая ответственность за проекты и их задачи | D5: РП каждого проекта и ответственный по каждой задаче внутри проекта КСГ проекта / актируемые этапы –план/факт сроков с ответственными
B6: Проекты ведутся по разным правилам: разные форматы, разные инструменты, разная детализация. Сравнивать проекты невозможно | D6: Единый ЖЦ проектов Единая структура этапов и КТ Единый формат дорожной карты проектов Единая шкала статусов готовности и % исполнения задач
B7: Экономика проекта и сроки ведутся в разных инструментах Не видны изменения бюджетов проектов при изменении сроков Отчетность по портфелю собирается вручную из разрозненных файлов. Подготовленный отчет уже не актуален | D7: Сквозное решение для управления сроками и бюджетами проектов Пользователь один раз задает сроки актирования и условия оплаты по проекту, а система сама рассчитывает сроки поступлений и платежей Актуализация данных в системе по мере возникновения информации, а не под отчет | F7: 0.8
B8: Факт по бюджетам ведется в учетной системе и не сопоставим с планом Нужно видеть факт в проектах вплоть до первичных документов Двойной ввод данных | D8: Ввод факта напрямую в системе или интеграции с учётными системами (опционально)
B9: Не получить актуальный прогноз по бюджетам портфеля с учетом фактических данных | D9: Автоматическая актуализация прогноза по факту (опционально) | F9: 0.8
F10: 0.5
F11: 0.5
F12: 0.8
F13: 0.8
F14: 0
F15: 0.5
B17: 2.2 Альтернативы | D17: 8. Ключевые метрики | I17: 5. Каналы | J17: 1.2 Ранние последователи
B18: Битрикс 24 Excel Он-лайн табличный процессор Адванта (базовый запуск) Яндекс трекер Импортозамещается: Шарепоинт + ПроджектСервер + Локальный Проджект + MS BI | D18: Количество продаж; Количество пользователей в ГРМ; Количество отзывов | J18: Х продаж за первые 3 мес.; У продаж за вторые 3 мес.
B19: 7. Структура издержек | H19: 6. Потоки прибыли
B22: решение не сформулировано | D22: Не занимались | E22: 0 | G22: Что нужно доработать:
B23: решение сформулировано частично | D23: В работе | E23: 0.1
B24: решение сформулировано | D24: Техническая реализация | E24: 0.5
D25: Базовая реализация (в т.ч. удобно) | E25: 0.8
D26: Глубокая реализация | E26: 1 | G26: Что нужно ОП для старта: демо-база, презентации.
B31: РАС Промблематика: | D31: Для кого: Генеральный директор (РПО)
B32: 1. Большое кол-во разразненной информации по проектам, не понятно на что уделить внимание - ключевые показатели всегда перед глазами онлайн | D32: Исполнитель - РП
B33: 1.1. Остутствие едиой среды ведения проектов - все ведут проекты по разному в разных инструментах
B34: 1.2. Остутсвие актуальной информации по проектам (на какой вехи/ кто за нее ответсвенный, попадаем ли в сроки, есть/нет ли рисков, подписаны ли акты, списание ДС. ) - тратим много времени на сбор акутальной информации | D34: Бизнес задача: Верхнеуровневый контроль состояния проектов реестра
B35: 1.3. РП Забывают внести данные - смотрим на ситуацию в прошлом
D36: Актуальная информация по реестру проектов в разрезе (анализ текущего состоянию проектов):
D37: КСГ проекта (актируемые этапы) план/факт сроков
D38: Контрольных точек ( Проектные решения - ответственных за них) план/факт исполнения КТ
D39: Потенциальные риски Есть/нет наличие
D40: БДР и БДДС - План/факт
D42: Факт и актуализация в ручном режиме
B46: сколько запросов под эту тематику за год было
B47: больше 2 млдр. Не Трудоемкое производство - 90 SQL
B48: как первый шаг на РМ5 для стандарт проектов - 119 SQL
B49: запросов какое количество было бы куплено
B50: больше 2 млдр. Не Трудоемкое производство - 19
B51: как первый шаг на РМ5 для стандарт проектов - 41
B52: какое количество заказчиков купило бы такое предложение из текущей воронки
...

Sheet ПиБпК_сопоставление
B2: Продукт | I2: Рынок
B3: 2.1 Проблема | C3: 2.1. Сопоставление с проблемами в презентации с вебинара | D3: =ROUND(AVERAGE(D6:D16),2) -> 0.5 | E3: 4. Решение | F3: Связь | G3: =AVERAGE(G4:G16) -> 0.61111111 | H3: 3. Уникальная ценность (УТП) | J3: 9. Скрытое преимущество | K3: 1.1 Сегменты потребителей
B4: 1.1. Остутствие единой среды ведения проектов - все ведут проекты в разных инструментах | C4: НА старте портфеля разрозненные инструменты работают, но по мере роста кол-ва проектов, появляются органичения. Существующая система перестала работать? (общая канва, не отдельная проблематика в презентации) | D4: =ROUND(AVERAGE(D8:D13),2) -> 0.39 | E4: Единое окно с набором актуальных показателей по реестру проектов (БДР, риски, сроки). Панель руководителя | F4: 1.1. | G4: 0.8 | H4: 1С:PM Создает единую управленческую среду где данные обновляются в процессе работы, а руководитель видит отклонение, ответсвенных и последствия в одном контуре: - Елиные правила управления (ПРоекты ведутся в общей логике: структура, роли и контрольные точки) - Контроль через отклонения (Руководитель видит где проблема и может сразу провалиться в причину) - Связь проектов и экономики (Сроки, жтапы и фин. показатели связаны между собой. Изменения сразу отражаются на бюджете) Порядок в проектах при любом текущем состоянии проектного управления Уверенная основа для дальнейшего развития проектного управления За счет айтисистемы и методической оддержки вы получите: Дашборд с консолидированной информацией о состоянии проектов (вехи, сроки, бюджеты, риски) Минимизация трудозатрат руководителя на получение информации о состоянии проектов Быстрый и легкий старт работы в системе Автомический контроль исполнительской дисциплины Стоимость до 2,5 млн., сроки - до 2х мес. запуска | J4: Богатый базовый фунционал решения Возможность повторения уникальной отчетности Возможность Интеграции с учетными системами: БУХ, УНФ, ERP | K4: Для компаний с начальным уровнем проектного управления (внешние проекты - оборот 800М до 4Я), (внутренние проекты - оборот от 2Я). Генеральный директор / РПО / ТОП Менеджер (ответсвенный за проектную деятельность) - потребитель отчетности от РП. осуществляет контроль за ходом реализации реестра проектов в одном окне (Вехи), показатели (план/факт сроки, бюджеты, риски). В основном контроль за внутренними проектами. РП (администратор проекта) - быстрое ведение проектов без детализации до объемов и ресурсов актуализация План/факт Вехи, сроки, бюджет, риски Тригеры: 1. Существующая система перестала работать из-за использования разрозненных инструментов, и отсетствия методики ведения проектов 2. Управленческие решения запаздывают из-за отсутсвия актуальной информации по проектам
B5: 1. Большое кол-во разрозненной информации по проектам, не понятно, на что уделить внимание - ключевые показатели всегда перед глазами онлайн | C5: Нет фокуса. Руководителю сложно понять, какие проекты требуют внимания
B6: 1.1. Остутствие единой среды ведения проектов - все ведут проекты по разному | C6: Проекты ведутся по разным правилам: разные форматы, разные инструменты, разная детализация. Сравнивать проекты невозможно | D6: =AVERAGE(G4,G7) -> 0.8 | E6: Совокупность Вех по всем проектам (аналог ВК в панели руководителя)
B7: 1.2. Остутсвие актуальной информации по проектам (на какой вехе/ кто за нее ответсвенный | C7: Размытая ответственность за проекты и их задачи | E7: Отвественные за проекты (РП), ответсвенные за задачи | F7: 1.1. | G7: 0.8
B8: 1.2. Остутсвие актуальной информации по проектам (, попадаем ли в сроки, есть/нет ли рисков, подписаны ли акты, списание ДС. ) - тратим много времени на сбор акутальной информации | C8: Экономика проекта и сроки ведутся в разных инструментах Не видны изменения бюджетов проектов при изменении сроков Отчетность по портфелю собирается вручную из разрозненных файлов. Подготовленный отчет уже не актуален | D8: =AVERAGE(G10,G9,G11,G12,G13) -> 0.68
B9: 1.3. РП Забывают внести данные - смотрим на ситуацию в прошлом | C9: Проблема: РП Забывают внести данные (Добавить новый раздел) | D9: =AVERAGE(G14) -> 0 | E9: КСГ проекта / актируемые этапы - план/факт сроков | F9: 1.2. | G9: 0.8
B10: 2. Оперативный и достоверный учет фактических данных по первичным документам - опция 1 | C10: Факт по бюджетам ведется в учетной системе и не сопоставим с планом Нужно видеть факт в проектах вплоть до первичных документов Двойной ввод данных | E10: Контрольных точек ( Проектные решения - ответственных за них) план/факт исполнения КТ; Вехам (из-за чего проиходит сдвиг, какие промблемы) | F10: 1.2. | G10: 0.5
B11: 3. Актуальный БДР и БДДС по портфелю (план и факт) - опция 2 | C11: Не получить актуальный прогноз по бюджетам портфеля с учетом фактических данных | E11: Потенциальные риски Есть/нет наличие | F11: 1.2. | G11: 0.5
E12: БДР и БДДС - План/факт | F12: 1.2. | G12: 0.8
B13: 1.4. Порядок | C13: Проблема: Система сама по себе не наводит порядок без правил. | D13: =AVERAGE(G15) -> 0.5 | E13: Факт и актуализация в ручном режиме | F13: 1.2. | G13: 0.8
E14: Автоматический контроль за актуализацией данных | F14: 1.3. | G14: 0
E15: Методическая поддержка | F15: 1.4. | G15: 0.5
B17: 2.2 Альтернативы | E17: 8. Ключевые метрики | J17: 5. Каналы | K17: 1.2 Ранние последователи
B18: Битрикс 24 Excel Он-лайн табличный процессор Адванта (базовый запуск) Яндекс трекер Импортозамещается: Шарепоинт + ПроджектСервер + Локальный Проджект + MS BI | E18: Количество продаж; Количество пользователей в ГРМ; Количество отзывов | K18: Х продаж за первые 3 мес.; У продаж за вторые 3 мес.
B19: 7. Структура издержек | I19: 6. Потоки прибыли
B22: решение не сформулировано | E22: Не занимались | F22: 0 | H22: Что нужно доработать:
B23: решение сформулировано частично | E23: В работе | F23: 0.1
B24: решение сформулировано | E24: Техническая реализация | F24: 0.5
E25: Базовая реализация (в т.ч. удобно) | F25: 0.8
E26: Глубокая реализация | F26: 1 | H26: Что нужно ОП для старта: демо-база, презентации.
B31: РАС Промблематика: | E31: Для кого: Генеральный директор (РПО)
B32: 1. Большое кол-во разразненной информации по проектам, не понятно на что уделить внимание - ключевые показатели всегда перед глазами онлайн | E32: Исполнитель - РП
B33: 1.1. Остутствие едиой среды ведения проектов - все ведут проекты по разному в разных инструментах
B34: 1.2. Остутсвие актуальной информации по проектам (на какой вехи/ кто за нее ответсвенный, попадаем ли в сроки, есть/нет ли рисков, подписаны ли акты, списание ДС. ) - тратим много времени на сбор акутальной информации | E34: Бизнес задача: Верхнеуровневый контроль состояния проектов реестра
B35: 1.3. РП Забывают внести данные - смотрим на ситуацию в прошлом
E36: Актуальная информация по реестру проектов в разрезе (анализ текущего состоянию проектов):
E37: КСГ проекта (актируемые этапы) план/факт сроков
E38: Контрольных точек ( Проектные решения - ответственных за них) план/факт исполнения КТ
E39: Потенциальные риски Есть/нет наличие
E40: БДР и БДДС - План/факт
E42: Факт и актуализация в ручном режиме
B46: сколько запросов под эту тематику за год было
B47: больше 2 млдр. Не Трудоемкое производство - 90 SQL
B48: как первый шаг на РМ5 для стандарт проектов - 119 SQL
B49: запросов какое количество было бы куплено
B50: больше 2 млдр. Не Трудоемкое производство - 19
B51: как первый шаг на РМ5 для стандарт проектов - 41
B52: какое количество заказчиков купило бы такое предложение из текущей воронки
...

Sheet 1+автоактуализация бюджетов
B2: Продукт | H2: Рынок
B3: 2.1 Проблема | C3: =ROUND(AVERAGE(C5:C14),2) -> 0.48 | D3: 4. Решение | E3: Связь | F3: =AVERAGE(F4:F14) -> 0.58181818 | G3: 3. Уникальная ценность (УТП) | I3: 9. Скрытое преимущество | J3: 1.1 Сегменты потребителей
B4: 1. Большое кол-во разразненной информации по проектам, не понятно на что уделить внимание - ключевые показатели всегда перед глазами онлайн | C4: =ROUND(AVERAGE(C6:C8),2) -> 0.39 | D4: Единое окно с набором актуальных показателей по реестру проектов (Вехи, БДР, риски, сроки). Панель руководителя | E4: 1.1. | F4: 0.8 | G4: Порядок в проектах при любом текущем состоянии проектного управления Дашборд с консолидированной информацией о состоянии проектов (вехи, сроки, бюджеты, риски) Минимизация трудозатрат руководителя на получение информации о состоянии проектов Быстрый и легкий старт работы в системе Автомическое контроль исполнительской дисциплины Интеграции с учетными системами: БП, УНФ, ERP (опционально) ОП: Стоимость от 3 до 5 млн., сроки - до 4х мес. запуска Производство: Стоимость до млн., сроки - до х мес. запуска | I4: Уверенная основа для дальнейшего развития проектного управления Богатый базовый фунционал решения Возможность повторения уникальной отчетности | J4: Для компаний с начальным уровнем проектного управления (внешние и внутренние проекты). Генеральный директор / РПО / ТОП Менеджер (ответсвенный за проетконую деятельность) - потребитель отчетности от РП. осуществляет контроль за ходом реализации реестра проектов в одном окне (Вехи), показатели (план/факт сроки, бюджеты, риски). В основном контроль за внутренними проектами. РП (администратор проекта) - быстрое ведение проектов без детализации до объемов и ресурсов актуализация План/факт Вехи, сроки, бюджет, риски
B5: 1.1. Остутствие единой среды ведения проектов - все ведут проекты по разному в разных инструментах | C5: =AVERAGE(F4,F5) -> 0.8 | D5: Ответственные за проекты (РП) | E5: 1.1. | F5: 0.8
B6: 1.2. Остутсвие актуальной информации по проектам (на какой вехи/ кто за нее ответсвенный, попадаем ли в сроки, есть/нет ли рисков, подписаны ли акты, списание ДС. ) - тратим много времени на сбор акутальной информации | C6: =AVERAGE(F7,F6,F8,F9,F10) -> 0.68 | D6: КСГ проекта / актируемые этапы - план/факт сроков | E6: 1.2. | F6: 0.8
B7: 1.3. РП Забывают внести данные - смотрим на ситуацию в прошлом | C7: =AVERAGE(F11) -> 0 | D7: Контрольные точки ( Проектные решения - ответственных за них) план/факт исполнения КТ; Вехам (из-за чего проиходит сдвиг, какие промблемы) | E7: 1.2. | F7: 0.5
B8: 1.4. Порядок | C8: =AVERAGE(F12) -> 0.5 | D8: Потенциальные риски Есть/нет наличие | E8: 1.2. | F8: 0.5
B9: 2. Оперативный и достоверный учет фактических данных по первичным документам - опция 1 | C9: =AVERAGE(F13) -> 0.8 | D9: БДР и БДДС - План/факт | E9: 1.2. | F9: 0.8
B10: 3. Актуальный БДР и БДДС по портфелю (план и факт) - опция 2 | C10: =AVERAGE(F14) -> 0.1 | D10: Факт и актуализация в ручном режиме | E10: 1.2. | F10: 0.8
D11: Автоматический контроль за актуализацией данных | E11: 1.3. | F11: 0
D12: Методическая поддержка | E12: 1.4. | F12: 0.5
D13: Интеграция для получения учетных данных из БП; Трансляция фактических данных из УНФ+РМ, ERP+РМ (опционально 1). | E13: 2 | F13: 0.8
D14: Механизм автоматической актуализации плановых данных по бюджетам (плана по факту) - (опционально 2) | E14: 3 | F14: 0.1
B15: 2.2 Альтернативы | D15: 8. Ключевые метрики | I15: 5. Каналы | J15: 1.2 Ранние последователи
B16: Битрикс 24 Excel Он-лайн табличный процессор Адванта (базовый запуск) Яндекс трекер Импортозамещается: Шарепоинт + ПроджектСервер + Локальный Проджект + MS BI | D16: Количество продаж; Количество пользователей в ГРМ; Количество отзывов | J16: Х продаж за первые 3 мес.; У продаж за вторые 3 мес.
B17: 7. Структура издержек | H17: 6. Потоки прибыли
B20: решение не сформулировано | D20: Не занимались | E20: 0 | G20: Что нужно доработать: | I20: Отчетность по ключевым вехам (как в ЦКБМ)
B21: решение сформулировано частично | D21: В работе | E21: 0.1 | I21: Механизм влияния рисков и других показателей (go, get, …) на расчет плановых данных
B22: решение сформулировано | D22: Техническая реализация | E22: 0.5 | I22: Интеграция с Битрикс24
D23: Базовая реализация (в т.ч. удобно) | E23: 0.8 | I23: Вехи в панели руководителя
D24: Глубокая реализация | E24: 1 | H24: Опция 2: | I24: Механизм автоматической актуализации плановых данных по бюджетам (плана по факту)
H26: Опции | I26: 1. вопрос Актуализации (без перевод всех планов в ручной режим. Это наше ключевое конкурентное преимущество и основа эффектов от автоматизации)
I27: 2. трансляция БДР в БДДС (не знаю сделана сейчас или нет, но на тот момент ее не было),
I28: 3. вопрос настроек трансляции в зависимости от договора (т.к. это влияет как раз на формирование ДДС)
B29: РАС Промблематика: | D29: Для кого: Генеральный директор (РПО) | I29: 4. ну и всеже работа с НДС у разных заказчиков с разными ставками. точно не знаю, но боюсь, что там сценарий не проверялся. сроков проекта
B30: 1. Большое кол-во разразненной информации по проектам, не понятно на что уделить внимание - ключевые показатели всегда перед глазами онлайн | D30: Исполнитель - РП | I30: 5. другие критичные задачи из бэклога очереди 2
B31: 1.1. Остутствие едиой среды ведения проектов - все ведут проекты по разному в разных инструментах
B32: 1.2. Остутсвие актуальной информации по проектам (на какой вехи/ кто за нее ответсвенный, попадаем ли в сроки, есть/нет ли рисков, подписаны ли акты, списание ДС. ) - тратим много времени на сбор акутальной информации | D32: Бизнес задача: Верхнеуровневый контроль состояния проектов реестра | I32: Равно БЗ 1 уровень ФД
B33: 1.3. РП Забывают внести данные - смотрим на ситуацию в прошлом
D34: Актуальная информация по реестру проектов в разрезе (анализ текущего состоянию проектов): | G34: Варианты оценки стоимости трансляции факта бюджетов в проетный контур и интеграций. Производственная оценка, без резервов
D35: КСГ проекта (актируемые этапы) план/факт сроков | G35: Вариант 1: | H35: 250 000 р + 2 недели к сроку проекта | I35: Трансляция данных первичных документов ERP+PM по основным хоз. операциям при налиции соответствующих аналитик учета | N35: может быть применим к Проекты и бюджеты под контролем при наличии соответствующих аналитик в документах
D36: Контрольных точек ( Проектные решения - ответственных за них) план/факт исполнения КТ | G36: Вариант 2: | H36: от 1500 000 р. От 2 месяцев | I36: Трансляция данных первичных документов ERP+PM по не стандартным хоз. операциям при налиции соответствующих аналитик учета
D37: Потенциальные риски Есть/нет наличие | I37: Подробная оценка по Варианту 1,2 по заполнению чек-листа: Чек-лист настройки правил трасляции из ERP в PM через Проектное бюджетирование: e1cib/data/Справочник.ВнутренниеДокументы?ref=8122000c295e34e311ef1e892acfb24d
D38: БДР и БДДС - План/факт | G38: Вариант 3: | H38: 250000 + 2 недели к сроку проекта | I38: Настройка типовых правил загрузки факта из БП 3.0 в PM (При их реализации в типовой и наличии соответсвующей детализации учета в Бухгалтерии, и готовности Бухгалтерии к интеграции в управленческими системами) | N38: может быть применим к Проекты и бюджеты под контролем при наличии соответствующих аналитик в документах
G39: Вариант 4: | H39: При разработке под Заказчика порядка 4-6 млн, срок 3 месяца | I39: НАИБОЛЕЕ вероятный, в реальной жизни: При неготовности учетной системы Заказчика (недостаточность аналитики в учете для автоматической перекладки данных правилами изи интеграцийе без двойного ввода) Необходимо прорабатывать рабочее место экономиста для корректного разнесения факта бюджетов по проектам вручную по данным отраженным в учете
D40: Факт и актуализация в ручном режиме
B44: сколько запросов под эту тематику за год было
B45: больше 2 млдр. Не Трудоемкое производство - 90 SQL
B46: как первый шаг на РМ5 для стандарт проектов - 119 SQL
B47: запросов какое количество было бы куплено
...

Sheet КапСтрой и инвестиции
B2: Продукт | H2: Рынок
B3: 2.1 Проблема | D3: 4. Решение | E3: Связь | F3: =AVERAGE(F4:F19) -> #DIV/0! | G3: 3. Уникальная ценность (УТП) | I3: 9. Скрытое преимущество | J3: 1.1 Сегменты потребителей
B4: 1. Огромные инвестиции, которые требуют контроля. Пример: Северсталь - 100млрд инвест.программа. 1 ошибка в планировании проекта, которая привела на 1 день просрочки простаивания ресурсов может стоить в большом проекте десятки миллионов рублей. | D4: Прединвестиционная стадия | G4: Единственное отраслевое решение на 1С, адаптированное для кап.строя и инвестиций Автоматизация актуализация прогноза с учетом фактических данных, получение фактических данных из учетных систем на 1С Единое информационное пространство по управлению инвест.программой компании Своевременнная индикация критичных отклонений по срокам и бюджетам проектов Продуманная связка с учетными системами компании | I4: Опыт лидеров отрасли, заложенный в решение Быстрая интеграция с существующей корпоративной архитектурой Бизнес-модель | J4: Сегмент - Ultra 10млрд+, все отрасли - Директор по инвестициям - или может быть бюджетом конкретного проекта - директор этого проекта Событие? Необходимость отказа от управления проектами кап.строя в Excel: 1) Павртия сказала через 2 года отказаться и перейти на отчественные решения, а российский аналог Excel не тянет требуемый функционал 2) Очень сильная зависимость от конкретных людей - например, всю модель управления разработал 1 человек, который может уйти в любой момент
B5: 2. Очень длительные проекты - чем больше горизонт планирования, тем сложнее строить отчетность + больше параллельных проектов, больше ошибок в планировании | D5: Решение для исполнения инвест.программы (что-то написать, чтобы разрулить B9 2-е предложение)
B6: 3. Необходимость отказа от управления проектами кап.строя в Excel. Почему уходят: - российский аналог Excel не тянет требуемый функционал: ...(конкретика) б). Очень сильная зависимость от конкретных людей - например, всю модель управления разработал 1 человек, который может уйти в любой момент | D6: Решение для исполнения инвест.проекта
B7: 4. Внутреннее спокойствие ЛПРа. Людей много, много экселей, много денег, а управляемости не чувствуется. | D7: Особенности: -- 3 ключевых показателя - освоение бюджета (объемы), финансирование (БДДС) и ввод объекта в эксплуатацию (БДР).
B8: В любой момент убедиться, что все в порядке, сроки не срываются и не сорвутся, из бюджета не вышли и не выйдем. Нужен факт и прогноз. | D8: -- факторный анализ отклонений по бюджетам - из-за чего произошли отклонения
B9: Управление одним монопроектом бывает, но редко. Чаще будет - управление исполнением инвестиционной программы (состояние каждого проекта в отдельности и исполнение инвест.программы на год) | D9: -- распределение затрат на объекты разные схемы
D10: -- важная аналитика - объект
B11: Если есть отклонения - кто их источник - какой отдел, подрядчик, по какому договору, | D11: -- валютный учёт (столкнулись в 2-х проектах) - например, бюджет поехал потому что изменился курс валют
D12: -- много интеграций (но нас выручает шина 1С, можно показать на шине структуру интеграции)
D13: -- интеграция по УХ
D14: -- S-кривые с прогнозом освоения и финансирования
B21: 2.2 Альтернативы | D21: 8. Ключевые метрики | I21: 5. Каналы | J21: 1.2 Ранние последователи
B22: Планнер, РМ-софт Excel | D22: Количество продаж; Количество пользователей в ГРМ; Количество отзывов | J22: Запросы за последние месяцы: Новатек, Роснефть, Эфко, Таиф, Евраз, Мособлэнерго - по каждому есть демо-базы Х продаж за первые 3 мес.; У продаж за вторые 3 мес.
B23: 7. Структура издержек | H23: 6. Потоки прибыли
B26: решение не сформулировано | D26: Не занимались | E26: 0 | G26: Что нужно доработать:
B27: решение сформулировано частично | D27: В работе | E27: 0.1
B28: решение сформулировано | D28: Техническая реализация | E28: 0.5
D29: Базовая реализация (в т.ч. удобно) | E29: 0.8
D30: Глубокая реализация | E30: 1 | G30: Что нужно ОП для старта: демо-база, презентации.
B33: У Айтиленд богатый опыт работы с кап.строем. Но есть внутр. ограничение - оценка от 100млн. Между тем, задачи можно стандартизировать. Глеб понимает, как.
B34: Нюансы: есть ли потребность в автоматизации прединвестиционного этапа (фин.моделирование, инвестиции, заявки, ранжирование, инвест.проекты)? Или реализация?
B35: Опыт - часто показываем из девеломпента т.к. там много общего
B36: Особенности: -- 3 ключевых показателя - освоение бюджета, финансирование и ввод объекта в эксплуатацию. -- факторный анализ отклонений по бюджетам - из-за чего произошли отклонения -- распределение затрат на объекты разные схемы -- важная аналитика - объект -- валютный учёт (столкнулись в 2-х проектах) - например, бюджет поехал потому что изменился курс валют -- много интеграций (но нас выручает шина 1С, можно показать на шине структуру интеграции)
B37: Портфели и программы
B38: Тематическое планирование
B39: Проекты, паспорт, KPI
B40: Дорожные карты проектов (Gates)
B41: Календарно-сетевое планирование
B42: Проектное бюджетирование
B43: Объемы проектов
B44: Материалы и оборудование проектов
... B50: Расширение: Математическое нормирование
B51: Расширение: Тендерная работа | C51: Уже есть в УХ
B52: Расширение: Распределение затрат | C52: Важно!
B53: Расширение: Перепланирование с учетом факта

Sheet от Лены
B2: Крупный бизнес (Стандарт.проекты, заказные проекты)
B3: ЛПР | C3: Проблемы/ Боли/ Задачи За что ЛПР будет готов заплатить 1млн.+ руб.? | D3: Потери/ недополученная прибыль
B4: Финансовый директор | C4: №1 Предсказуемость и управляемость (Скорость и качество управленческих решений, возможность влиять на ситуацию) То, чт о раньше было просто - теперь стало сложно (отчетность). Нужно переходить от EXCEL - Куда-то. Куда пока не ясно. Сводные данные по конторе - есть и без нас. Шаг 1 - им нужна информация по маржинальности по подразделениям с возможностью провалиться до первички Шаг 2 - нужен переход от котлового учета, чтобы внутри подразделений видеть маржинальность до уровня направлений/ проектов | D4: Невозможно управлять маржинальностью, отсюда большие финансовые потери, низкая скорость реакции и неверные управленческие решения
C5: №2 Рост маржинальности портфеля проектов за счет управляемости - из-за сдвигов сроков и внеплановых затрат снижается маржинальность - Нет оценки проектов - При оценке маржинальности проектов не учитывается стоимость денег - … дополнить | D5: Не выполняется план по прибыли Большие финансовые потери Нет понимания, как выйти на желаемую прибыль
C6: №3 Актуальный бюджет и Прибыль организации - Бюджет теряет актуальность уже через 1-2 месяца т.к. ситуация на проектах меняется - Учетная система зачастую не содержит информации о перспективных объемов, их планируют общей суммой (серая зона = зона нехватки объемов), поэтому невозможно оценить прогресс контрактации и осуществимость этих планов. - подразделения не отвечают за прибыль, расходы растут, не понятно какие из них действительно нужны, а какие можно срезать - Инвестиционные расходы в итоге выше, чем прибыль организации | D6: Не выполняется план по прибыли Нет возможности повлиять на ситуацию, когда ещё можно Инвестиции превышают доходы компании или наоборот, упущенная выгода от того что не вложили в развитие
C7: №4 Предотвращение кассовых разрывов и контроль ликвидности (является прямым следствием маржинальности организации) - Из-за неактуальных данных кассовые разрывы чаще всего не видны - Из-за этого постоянно приходится "тушить пожары" - Что в свою очередь снижает рентабельность бизнеса | D7: Снижение маржинальности бизнеса (прибыли) из-за "внезапных" кассовых разрывов, погасить которые стоит дорого
C8: №5 Дефицит бюджета т.к. турбулентность на рынке, не выполняются планы по объемам
B9: Директор по производству | C9: №1 Регулярные срывы сроков по проектам и перерасход нормочасов - не можем вовремя увидеть, где есть отклонения по проекту и принять меры, часто принимаем интуитивные решения а не на основе цифр, Перерасход по нормочасам видим, когда исправить уже ничего нельзя - Нельзя сравнить проекты между собой. В итоге - не выстроить внятные контролируемые показатели - Разные подразделения не понимают кто что делает. Взаимодействуют через руководителя. В итоге- нарушена коммуникация участников внутри проекта. Ручное разруливание конфликтов лично руководителем - Специалисты на проектах делают то, что им удобно, а не то что нужно по графику В итоге - это ставит под угрозу срывы сроков на проектах | D9: Прямые финансовые потери на перерасходах. Условно: на проекте стоимостью 1млн.руб. потери могут составлять 200-300тыс.
C10: №2 Выполнение объемов: Не выполнить / непонимаю как выполнить план, который мне ставят, текущими ресурсами, а руководство настаивает - Нет взаимосвязей между разными проектами. Сложно проследить, как сдвиг сроков на одном проекте влияет на другой проект. В итоге - ситуации, когда люди перегружены и рарываются между проектами и мы не можем выполнить объем. - Нет синхронизации с планами по продажам. В итоге приходят выгодные контракты, которые мы не можем начать выполнять из-за нехватки мощности. - Не понимаем при старте проекта, выполним ли он в указанные сроки или нет. В итоге - берем проект, сроки все время на грани срывов. - Страдает качество и актуальность экономических и финансовых данных по проектной деятельности | D10: Не получается масштабировать
C11: №3 Не хвататет объемов, чтобы обеспечить загрузку сотрудников. Простои. | D11: Прямые убытки - ЗП платим, доходы снижаются, люди не загружены
C12: №4 Маржинальность портфеля проектов - Не понимаем, насколько необходимо делать все эти работы, которые списываем на проект - Не понимаем, насколько корректно мы оцениваем будущие проекты из-за кривой статистики - Не понимаем актуальную загрузку (свободную мощность подразделения, текущие трудовые резервы) - Понимаем, что есть недополученная прибыль, но за счет чего ее можно добиться - непонятно. - Каждый проект вынуждены выполнять как уникальный, несмотря на то, что есть "типовые задачи", как следствие проекты менее маржинальны | D12: Упущенная выгода. Прибыли можно получать больше!
C13: №5 Команда: Ключевые специалисты перегружены - "Бегство" ключевых специалистов из-за хаоса и выгорания
B14: Генеральный директор. | C14: 1. Прозрачность, управлемость порядок - Нет актуальной аналитики. Решения принимаются вслепую или на основе неактуальных данных. - Непредсказуемость сроков и хронические срывы сроков. | D14: - Потери от неправильных решений - неправильные решения ТОПового уровня ведут к Потери миллионов - авральный режим работы - упущенная выгода от Потери клиента - репутационные риски - вплодь до Потери бизнеса.
C15: 2. Повышение прибыльности/маржинальности бизнеса за счет повышения эффективности процессов и сокращения расходов - Неконтролируемые финансовые потери по проектам (из-за срыва сроков, перерасходов по трудозатратам, недоучтенным материалам >20-30%) - Рост накладных расходов | D15: Прямые финансовые потери на перерасходах. Условно: на проекте стоимостью 1млн.руб. потери могут составлять 200-300тыс.
C16: 3. Масштабирование бизнеса - брать больше проектов и не терять в качестве - Перегрузка ключевых сотрудников - Хаос в процессах. Нет регламентов, нормативов. Сотрудники делают что им хочется, а не то что нужно - Все проекты "индивидуальные", отсутсвует единая методология ведения проектов - Постоянные конфликты между отделами, парализующие работу (отдел продаж продает нереализуемое, производство не успевает, финансы блокируют все инициативы) | D16: - Нехватка квалифицированных кадров, не можем брать больше проектов - Мы не можем тиражировать успешные практики, теряем прибыль - Страдает качество и репутация
C17: 4. Выжить в условиях турбулентности. Сохранить прибыль. Не потерять команду.

Sheet Соло
B2: Продукт | H2: Рынок
B3: 2.1 Проблема | C3: =ROUND(AVERAGE(C4:C15)*100,0) -> 27 | D3: 4. Решение | E3: Связь | F3: =AVERAGE(F4:F15) -> 0.34545455 | G3: 3. Уникальная ценность (УТП) | I3: 9. Скрытое преимущество | J3: 1.1 Сегменты потребителей
B4: 1) Нет единой системы управления проектами и проектного документооборота (~MDR базовый) | C4: =AVERAGE(F5,F6) -> 0.25 | D4: Комплексная система по управлению проектом для РП, обеспечивающая: | G4: Комплексная система для РП по управлению проектами, ресурсами и финансами проектов, проектным документооборотом | I4: Интеграция с CRM-системой (УНФ или Б24); Возможность доработки; Облако-коробка. | J4: РП из проектного офиса под свои проекты, которому нужно передавать результаты заказчику, управлять на основе разнородных данных и формировать стандартизированную регулярную честную отчетность руководству. Увеличивается объем проектов, нужно автоматизировать рутинные операции, уменьшить к-во ошибок.
